Workbook

Sheet DETALLE RAMO MADRE 
B2: Semestre | C2: Codigo_ID | D2: Siglas | E2: Nombre | F2: SECCION | G2: N° ALUMNOS
B3: 1 | C3: CUR001 | D3: TIC | E3: Taller introductorio a la cocina | F3: 1 | G3: 18
B4: 1 | C4: CUR001 | D4: TIC | E4: Taller introductorio a la cocina | F4: 2 | G4: 18
B5: 1 | C5: CUR001 | D5: TIC | E5: Taller introductorio a la cocina | F5: 3 | G5: 16
B6: 1 | C6: CUR001 | D6: TIC | E6: Taller introductorio a la cocina | F6: 4 | G6: 16
B7: 1 | C7: CUR001 | D7: TIC | E7: Taller introductorio a la cocina | F7: 5 | G7: 17
B8: 2 | C8: CUR002 | D8: TIP | E8: Taller introductorio a la pasteleria | F8: 1 | G8: 18
B9: 2 | C9: CUR002 | D9: TIP | E9: Taller introductorio a la pasteleria | F9: 2 | G9: 18
B10: 2 | C10: CUR002 | D10: TIP | E10: Taller introductorio a la pasteleria | F10: 3 | G10: 16
B11: 2 | C11: CUR002 | D11: TIP | E11: Taller introductorio a la pasteleria | F11: 4 | G11: 16
B12: 2 | C12: CUR002 | D12: TIP | E12: Taller introductorio a la pasteleria | F12: 5 | G12: 17
B13: 3 | C13: CUR003 | D13: TCCM | E13: Taller de cocina chilena y del mundo | F13: 1 | G13: 20
B14: 3 | C14: CUR003 | D14: TCCM | E14: Taller de cocina chilena y del mundo | F14: 2 | G14: 20
... B60: 8 | C60: CUR014 | D60: TEAC | E60: Taller de emprendimientos culinarios | F60: 4 | G60: 16

Sheet DETALLE DE SUB-RAMOS MENSUALES
B1: SEMESTRE | C1: CODIGO_ID | D1: SIGLAS | E1: NOMBRE | F1: MES | G1: OP
B2: 1 | C2: CUR001 | D2: TIC | E2: Taller integrado de restaurante | F2: MARZO | G2: TICSES1
G3: TICSES2
G4: TICSES3
G5: TICSES4
G6: TICSES5
G7: TICSES6
F8: ABRIL | G8: TICSES7
G9: TICSES8
G10: TICSES9
G11: TICSES10
G12: TICSES11
G13: TICSES12
G14: TICSES13
G15: TICSES14
G16: TICSES15
F17: MAYO | G17: TICSES16
G18: TICSES17
G19: TICSES18
G20: TICSES19
G21: TICSES20
G22: TICSES21
G23: TICSES22
G24: TICSES23
F25: JUNIO | G25: TICSES24
G26: TICSES26
G27: TICSES27
G28: TICSES28
G29: TICSES29
G30: TICSES30
F31: JULIO | G31: TICSES32
G32: TICSES34
B33: 2 | C33: CUR002 | D33: TIP | E33: Taller introductorio a la pasteleria | F33: AGOSTO | G33: TIPSES3
G34: TIPSES4
G35: TIPSES5
G36: TIPSES6
G37: TIPSES7
G38: TIPSES8
F39: SEPTIEMBRE | G39: TIPSES9
G40: TIPSES10
...

Sheet INGREDIENTES DE SUB-RAMOS
B1: RAMO | C1: SUB-RAMO | D1: INGREDIENTE | E1: CANTIDAD | F1: UM | G1: CATEGORIA | H1: nn
B2: TIC | C2: TICSES1 | D2: ZANAHORIA | E2: 0.2 | F2: kg | G2: FRUTA VERDURA | H2: =VLOOKUP(D2,'DETALLE PRECIO INGREDIENTES'!B:B,1,0) -> ZANAHORIA
B3: TIC | C3: TICSES1 | D3: PIMIENTO ROJO | E3: 0.5 | F3: UN | G3: FRUTA VERDURA | H3: =VLOOKUP(D3,'DETALLE PRECIO INGREDIENTES'!B:B,1,0) -> PIMIENTO ROJO
B4: TIC | C4: TICSES1 | D4: PAPAS | E4: 0.2 | F4: kg | G4: FRUTA VERDURA | H4: =VLOOKUP(D4,'DETALLE PRECIO INGREDIENTES'!B:B,1,0) -> PAPAS
B5: TIC | C5: TICSES1 | D5: AJO CABEZA | E5: 0.2 | F5: UN | G5: FRUTA VERDURA | H5: =VLOOKUP(D5,'DETALLE PRECIO INGREDIENTES'!B:B,1,0) -> AJO CABEZA
B6: TIC | C6: TICSES1 | D6: CEBOLLA BLANCA | E6: 0.2 | F6: kg | G6: FRUTA VERDURA | H6: =VLOOKUP(D6,'DETALLE PRECIO INGREDIENTES'!B:B,1,0) -> CEBOLLA BLANCA
B7: TIC | C7: TICSES1 | D7: APIO MATA | E7: 0.1 | F7: UN | G7: FRUTA VERDURA | H7: =VLOOKUP(D7,'DETALLE PRECIO INGREDIENTES'!B:B,1,0) -> APIO MATA
B8: TIC | C8: TICSES1 | D8: PUERROS | E8: 0.2 | F8: UN | G8: FRUTA VERDURA | H8: =VLOOKUP(D8,'DETALLE PRECIO INGREDIENTES'!B:B,1,0) -> PUERROS
B9: TIC | C9: TICSES1 | D9: CEBOLLIN | E9: 0.5 | F9: UN | G9: FRUTA VERDURA | H9: =VLOOKUP(D9,'DETALLE PRECIO INGREDIENTES'!B:B,1,0) -> CEBOLLIN
B10: TIC | C10: TICSES2 | D10: AJO CABEZA | E10: 0.2 | F10: UN | G10: FRUTA VERDURA | H10: =VLOOKUP(D10,'DETALLE PRECIO INGREDIENTES'!B:B,1,0) -> AJO CABEZA
B11: TIC | C11: TICSES2 | D11: CEBOLLA BLANCA | E11: 0.2 | F11: kg | G11: FRUTA VERDURA | H11: =VLOOKUP(D11,'DETALLE PRECIO INGREDIENTES'!B:B,1,0) -> CEBOLLA BLANCA
B12: TIC | C12: TICSES2 | D12: PIMIENTO ROJO | E12: 0.5 | F12: UN | G12: FRUTA VERDURA | H12: =VLOOKUP(D12,'DETALLE PRECIO INGREDIENTES'!B:B,1,0) -> PIMIENTO ROJO
B13: TIC | C13: TICSES2 | D13: REPOLLO | E13: 0.125 | F13: UN | G13: FRUTA VERDURA | H13: =VLOOKUP(D13,'DETALLE PRECIO INGREDIENTES'!B:B,1,0) -> REPOLLO
... B348: TIC | C348: TICSES19 | D348: POLLO PECHUGA ENTERA UN | E348: 0.5 | F348: UN | G348: POLLO | H348: =VLOOKUP(D348,'DETALLE PRECIO INGREDIENTES'!B:B,1,0) -> #N/A
B349: TIC | C349: TICSES19 | D349: ACEITE PARA FREIR | E349: 0.12 | F349: #REF! | G349: #REF! | H349: =VLOOKUP(D349,'DETALLE PRECIO INGREDIENTES'!B:B,1,0) -> ACEITE PARA FREIR
B350: TIC | C350: TICSES19 | D350: POLLO TRUTRO ALA | E350: 0.12 | F350: kg | G350: POLLO | H350: =VLOOKUP(D350,'DETALLE PRECIO INGREDIENTES'!B:B,1,0) -> POLLO TRUTRO ALA
B351: TIC | C351: TICSES19 | D351: AJO EN POLVO | E351: 0.001 | F351: kg | G351: ABARROTE | H351: =VLOOKUP(D351,'DETALLE PRECIO INGREDIENTES'!B:B,1,0) -> AJO EN POLVO
B352: TIC | C352: TICSES19 | D352: PIMIENTA CAYENA | E352: 0.002 | F352: kg | G352: ABARROTE | H352: =VLOOKUP(D352,'DETALLE PRECIO INGREDIENTES'!B:B,1,0) -> PIMIENTA CAYENA
B353: TIC | C353: TICSES19 | D353: AJI TABASCO ROJO | E353: 0.004 | F353: L | G353: ABARROTE | H353: =VLOOKUP(D353,'DETALLE PRECIO INGREDIENTES'!B:B,1,0) -> AJI TABASCO ROJO
B354: TIC | C354: TICSES19 | D354: SALSA INGLESA | E354: 0.003 | F354: L | G354: ABARROTE | H354: =VLOOKUP(D354,'DETALLE PRECIO INGREDIENTES'!B:B,1,0) -> SALSA INGLESA
B355: TIC | C355: TICSES19 | D355: MANTEQUILLA CON SAL | E355: 0.04 | F355: kg | G355: LACTEO | H355: =VLOOKUP(D355,'DETALLE PRECIO INGREDIENTES'!B:B,1,0) -> MANTEQUILLA CON SAL
B356: TIC | C356: TICSES19 | D356: VINAGRE BLANCO | E356: 0.012 | F356: L | G356: ABARROTE | H356: =VLOOKUP(D356,'DETALLE PRECIO INGREDIENTES'!B:B,1,0) -> VINAGRE BLANCO
B357: TIC | C357: TICSES19 | D357: AJI SRIRACHA | E357: 0.023 | F357: kg | G357: ABARROTE | H357: =VLOOKUP(D357,'DETALLE PRECIO INGREDIENTES'!B:B,1,0) -> AJI SRIRACHA
B358: TIC | C358: TICSES19 | D358: AZUCAR BLANCA GRANULADA | E358: 0.02 | F358: kg | G358: ABARROTE | H358: =VLOOKUP(D358,'DETALLE PRECIO INGREDIENTES'!B:B,1,0) -> AZUCAR BLANCA GRANULADA
B359: TIC | C359: TICSES19 | D359: HARINA BIZCOCHERA | E359: 0.05 | F359: kg | G359: ABARROTE | H359: =VLOOKUP(D359,'DETALLE PRECIO INGREDIENTES'!B:B,1,0) -> HARINA BIZCOCHERA
B360: TIC | C360: TICSES19 | D360: MAICENA | E360: 0.025 | F360: kg | G360: ABARROTE | H360: =VLOOKUP(D360,'DETALLE PRECIO INGREDIENTES'!B:B,1,0) -> MAICENA
B361: TIC | C361: TICSES19 | D361: PAPRIKA | E361: 0.001 | F361: kg | G361: ABARROTE | H361: =VLOOKUP(D361,'DETALLE PRECIO INGREDIENTES'!B:B,1,0) -> PAPRIKA
... B1448: TBD | C1448: TBDSES3 | D1448: LEVADURA FRESCA | E1448: 0.004 | F1448: kg | G1448: ABARROTE | H1448: =VLOOKUP(D1448,'DETALLE PRECIO INGREDIENTES'!B:B,1,0) -> LEVADURA FRESCA
B1449: TBD | C1449: TBDSES3 | D1449: MANJAR NESTLE | E1449: 0.165 | F1449: #N/A | G1449: #N/A | H1449: =VLOOKUP(D1449,'DETALLE PRECIO INGREDIENTES'!B:B,1,0) -> #N/A
B1450: TBD | C1450: TBDSES3 | D1450: MERMELADA DE FRAMBUESA | E1450: 0.085 | F1450: kg | G1450: ABARROTE | H1450: =VLOOKUP(D1450,'DETALLE PRECIO INGREDIENTES'!B:B,1,0) -> MERMELADA DE FRAMBUESA
B1451: TBD | C1451: TBDSES3 | D1451: CREMA DE LECHE | E1451: 0.2 | F1451: L | G1451: LACTEO | H1451: =VLOOKUP(D1451,'DETALLE PRECIO INGREDIENTES'!B:B,1,0) -> CREMA DE LECHE
B1452: TBD | C1452: TBDSES3 | D1452: LECHE ENTERA | E1452: 0.18 | F1452: L | G1452: LACTEO | H1452: =VLOOKUP(D1452,'DETALLE PRECIO INGREDIENTES'!B:B,1,0) -> LECHE ENTERA
B1453: TBD | C1453: TBDSES3 | D1453: PISCO CAPEL 35º | E1453: 0.01 | F1453: UN | G1453: LICOR | H1453: =VLOOKUP(D1453,'DETALLE PRECIO INGREDIENTES'!B:B,1,0) -> PISCO CAPEL 35º
B1454: TBD | C1454: TBDSES3 | D1454: CAFE EN SACHET | E1454: 1.5 | F1454: UN | G1454: ABARROTE | H1454: =VLOOKUP(D1454,'DETALLE PRECIO INGREDIENTES'!B:B,1,0) -> CAFE EN SACHET
B1455: TBD | C1455: TBDSES3 | D1455: TE LIPTON BOLSA | E1455: 1.5 | F1455: UN | G1455: TE | H1455: =VLOOKUP(D1455,'DETALLE PRECIO INGREDIENTES'!B:B,1,0) -> TE LIPTON BOLSA
B1456: TBD | C1456: TBDSES3 | D1456: PULPA DE FRUTILLA | E1456: 0.08 | F1456: kg | G1456: CONGELADO | H1456: =VLOOKUP(D1456,'DETALLE PRECIO INGREDIENTES'!B:B,1,0) -> PULPA DE FRUTILLA
B1457: TBD | C1457: TBDSES3 | D1457: PAPEL CERESINADO PLIEGO | E1457: 1 | F1457: UN | G1457: ARTICULO COCINA | H1457: =VLOOKUP(D1457,'DETALLE PRECIO INGREDIENTES'!B:B,1,0) -> PAPEL CERESINADO PLIEGO
B1458: TBD | C1458: TBDSES3 | D1458: QUESO GAUDA LAMINADO | E1458: 0.05 | F1458: kg | G1458: LACTEO | H1458: =VLOOKUP(D1458,'DETALLE PRECIO INGREDIENTES'!B:B,1,0) -> QUESO GAUDA LAMINADO
B1459: TBD | C1459: TBDSES3 | D1459: JAMON ACARAMELADO LAMINADO | E1459: 0.05 | F1459: kg | G1459: JAMON | H1459: =VLOOKUP(D1459,'DETALLE PRECIO INGREDIENTES'!B:B,1,0) -> JAMON ACARAMELADO LAMINADO
B1460: TBD | C1460: TBDSES3 | D1460: PIMIENTO MORRON | E1460: 0.25 | F1460: UN | G1460: FRUTA VERDURA | H1460: =VLOOKUP(D1460,'DETALLE PRECIO INGREDIENTES'!B:B,1,0) -> PIMIENTO MORRON
...

Sheet DETALLE PRECIO INGREDIENTES
A1: CATEGORIA | B1: INGREDIENTE | C1: Proveedor | D1: Suma de CANT. TOTAL | E1: Formato | F1: MEDIDA | G1: NETO | H1: BRUTO
A2: ABARROTE | B2: ACEITE DE CANOLA | C2: Jumbo | D2: 0.02 | E2: 1 | F2: L | G2: 2731 | H2: =G2*1.19 -> 3249.89
A3: ABARROTE | B3: ACEITE DE COCO | C3: lider | D3: 0.01125 | E3: 400 | F3: CC | G3: 4361 | H3: =G3*1.19 -> 5189.59
A4: ABARROTE | B4: ACEITE DE MAIZ | C4: Jumbo | D4: 0.00375 | E4: 1 | F4: L | G4: 3471 | H4: =G4*1.19 -> 4130.49
A5: ABARROTE | B5: ACEITE DE MARAVILLA | C5: Bidfood | D5: 1.756625 | E5: 5 | F5: L | G5: 12372 | H5: =G5*1.19 -> 14722.68
A6: ABARROTE | B6: ACEITE DE OLIVA | C6: Bidfood | D6: 1.0346875 | E6: 5 | F6: L | G6: 23840 | H6: =G6*1.19 -> 28369.6
A7: ABARROTE | B7: ACEITE DE SESAMO | C7: Lider | D7: 0.015625 | E7: 185 | F7: CC | G7: 5034 | H7: =G7*1.19 -> 5990.46
A8: ABARROTE | B8: ACEITE PARA FREIR | C8: Bidfood | D8: 4.45 | E8: 10 | F8: L | G8: 23928 | H8: =G8*1.19 -> 28474.32
A9: ABARROTE | B9: ACEITE SEMILLA DE GIRASOL | C9: Bidfood | D9: 0.1725 | E9: 1 | F9: L | G9: 3390 | H9: =G9*1.19 -> 4034.1
A10: ABARROTE | B10: ACEITE VEGETAL | C10: Bidfood | D10: 1.87825 | E10: 5 | F10: L | G10: 10178 | H10: =G10*1.19 -> 12111.82
A11: ABARROTE | B11: ACEITUNAS MORADAS | C11: Jumbo | D11: 0.015625 | E11: 200 | F11: GR | G11: 2765 | H11: =G11*1.19 -> 3290.35
A12: ABARROTE | B12: ACEITUNAS NEGRAS C/HUESO | C12: Bidfood | D12: 0.009375 | E12: 1 | F12: KG | G12: 4150 | H12: =G12*1.19 -> 4938.5
A13: ABARROTE | B13: ACEITUNAS NEGRAS S/HUESO | C13: Bidfood | D13: 0.2075 | E13: 850 | F13: GR | G13: 5781 | H13: =G13*1.19 -> 6879.39
... A353: EMBUTIDO | B353: VIENESA | C353: Ganadera Real | D353: 1 | E353: 1 | F353: KG | G353: 4650 | H353: =G353*1.19 -> 5533.5
A354: ENCURTIDO | B354: CHUCRUT ENCURTIDO | C354: Bidfood | E354: 1 | F354: KG | G354: 2259 | H354: =G354*1.19 -> 2688.21
A355: ENDULZANTE | B355: SUCRALOSA SOBRE | C355: Farmacia | D355: 2 | E355: 200 | F355: UN | G355: 6546 | H355: =G355*1.19 -> 7789.74
A356: ENDULZANTE | B356: SUCRO EMUL | C356: Farmacia | D356: 0.001125 | E356: 1 | F356: UN | G356: 22689 | H356: =G356*1.19 -> 26999.91
A357: ENDULZANTE | B357: TAGATOSA | C357: Lider | D357: 0.00525 | E357: 500 | F357: GR | G357: 6546 | H357: =G357*1.19 -> 7789.74
A358: ESPORAS | B358: PENICILLIUM CANDIUM 10 DOSIS | C358: Fermentos del sur | D358: 8.75e-05 | E358: 1 | F358: L | G358: 23521 | H358: =G358*1.19 -> 27989.99
A359: ESPORAS | B359: PENICILLIUM ROQUEFORTI 50 ML | C359: Fermentos del sur | D359: 7.5e-05 | E359: 1 | F359: L | G359: 42008 | H359: =G359*1.19 -> 49989.52
A360: FRUTA VERDURA | B360: ACELGA | C360: Caserita | D360: 0.07 | E360: 1 | F360: KG | G360: 1092 | H360: =G360*1.19 -> 1299.48
A361: FRUTA VERDURA | B361: aji amarillo | C361: Caserita | D361: 0.035 | E361: 1 | F361: KG | G361: 6555 | H361: =G361*1.19 -> 7800.45
A362: FRUTA VERDURA | B362: AJI CACHO CABRA AHUMADO | C362: Caserita | D362: 1.5125625 | E362: 1 | F362: KG | G362: 10924 | H362: =G362*1.19 -> 12999.56
A363: FRUTA VERDURA | B363: AJI CACHO DE CABRA FRESCO | C363: Caserita | D363: 0.015625 | E363: 1 | F363: KG | G363: 5462 | H363: =G363*1.19 -> 6499.78
A364: FRUTA VERDURA | B364: AJI ROCOTO | C364: Caserita | D364: 0.278125 | E364: 1 | F364: KG | G364: 18571 | H364: =G364*1.19 -> 22099.49
A365: FRUTA VERDURA | B365: AJI VERDE | C365: Caserita | D365: 0.42375 | E365: 1 | F365: KG | G365: 3824 | H365: =G365*1.19 -> 4550.56
A366: FRUTA VERDURA | B366: AJO CABEZA | C366: Caserita | D366: 10.36425 | E366: 1 | F366: un | G366: 219 | H366: =G366*1.19 -> 260.61
... A606: MASA | B606: MASA FILO | C606: Lider | D606: 0.0625 | E606: 330 | F606: GR | G606: 5370 | H606: =G606*1.19 -> 6390.3
