Workbook

Sheet DASHBOARD
A1: DASHBOARD
B5: TOTAL PRODUCTOS | D5: CATEGORÍAS | F5: PROVEEDORES | H5: COSTO TOTAL EST.
B6: =COUNTA('CONSOLIDADO PRECIOS'!B$5:B$646)-COUNTIF('CONSOLIDADO PRECIOS'!B$5:B$646,"") -> 574 | D6: =COUNTA(RESUMEN!A3:A36) -> 34 | F6: =COUNTA(PROVEEDORES!A3:A42) -> 40 | H6: =RESUMEN!D37 -> 8279311.2
B8: Factor de incremento: | D8: ='CONSOLIDADO PRECIOS'!B2 -> 0.1
B10: COSTO ESTIMADO TOTAL POR CATEGORÍA
B11: CATEGORÍA | D11: N° PROD. | F11: PROM. ESTIMADO | H11: TOTAL ESTIMADO
B12: =RESUMEN!A3 -> ABARROTE | D12: =RESUMEN!B3 -> 240 | F12: =RESUMEN!C3 -> 18165.546 | H12: =RESUMEN!D3 -> 4341565.4
B13: =RESUMEN!A4 -> AGUA | D13: =RESUMEN!B4 -> 3 | F13: =RESUMEN!C4 -> 7667 | H13: =RESUMEN!D4 -> 15334
B14: =RESUMEN!A5 -> ALGAS | D14: =RESUMEN!B5 -> 2 | F14: =RESUMEN!C5 -> 9824.8333 | H14: =RESUMEN!D5 -> 9824.8333
B15: =RESUMEN!A6 -> ARTICULO COCINA | D15: =RESUMEN!B6 -> 35 | F15: =RESUMEN!C6 -> 2572.2529 | H15: =RESUMEN!D6 -> 87456.6
B16: =RESUMEN!A7 -> BROTES | D16: =RESUMEN!B7 -> 2 | F16: =RESUMEN!C7 -> 3575.3667 | H16: =RESUMEN!D7 -> 3575.3667
B17: =RESUMEN!A8 -> CABRITO | D17: =RESUMEN!B8 -> 2 | F17: =RESUMEN!C8 -> 24334.567 | H17: =RESUMEN!D8 -> 24334.567
B18: =RESUMEN!A9 -> CERDO | D18: =RESUMEN!B9 -> 22 | F18: =RESUMEN!C9 -> 14539.905 | H18: =RESUMEN!D9 -> 305338
B19: =RESUMEN!A10 -> CERVEZA | D19: =RESUMEN!B10 -> 2 | F19: =RESUMEN!C10 -> 5725.5 | H19: =RESUMEN!D10 -> 5725.5
B20: =RESUMEN!A11 -> CHOCOLATE | D20: =RESUMEN!B11 -> 22 | F20: =RESUMEN!C11 -> 17098.417 | H20: =RESUMEN!D11 -> 359066.77
B21: =RESUMEN!A12 -> COLORANTES | D21: =RESUMEN!B12 -> 14 | F21: =RESUMEN!C12 -> 19172.69 | H21: =RESUMEN!D12 -> 249244.97
B22: =RESUMEN!A13 -> CONGELADO | D22: =RESUMEN!B13 -> 14 | F22: =RESUMEN!C13 -> 5833.1731 | H22: =RESUMEN!D13 -> 75831.25
B23: =RESUMEN!A14 -> CONSERVA | D23: =RESUMEN!B14 -> 5 | F23: =RESUMEN!C14 -> 5490.5583 | H23: =RESUMEN!D14 -> 21962.233
... B45: =RESUMEN!A36 -> YOGURT | D45: =RESUMEN!B36 -> 4 | F45: =RESUMEN!C36 -> 3064.8444 | H45: =RESUMEN!D36 -> 9194.5333
B46: TOTAL | D46: =RESUMEN!B37 -> 642 | H46: =RESUMEN!D37 -> 8279311.2
B48: TOP 10 — PRODUCTOS CON MAYOR PRECIO ESTIMADO
B49: INGREDIENTE | E49: CATEGORÍA | H49: PRECIO ESTIMADO
B50: =IFERROR(INDEX('CONSOLIDADO PRECIOS'!$B$5:$B$646,MATCH(LARGE('CONSOLIDADO PRECIOS'!$U$5:$U$646,1),'CONSOLIDADO PRECIOS'!$U$5:$U$646,0)),"") -> BAYAS DE ENEBRO | E50: =IFERROR(INDEX('CONSOLIDADO PRECIOS'!$A$5:$A$646,MATCH(LARGE('CONSOLIDADO PRECIOS'!$U$5:$U$646,1),'CONSOLIDADO PRECIOS'!$U$5:$U$646,0)),"") -> FRUTA VERDURA | H50: =IFERROR(LARGE('CONSOLIDADO PRECIOS'!$U$5:$U$646,1),"") -> 250252.2
B51: =IFERROR(INDEX('CONSOLIDADO PRECIOS'!$B$5:$B$646,MATCH(LARGE('CONSOLIDADO PRECIOS'!$U$5:$U$646,2),'CONSOLIDADO PRECIOS'!$U$5:$U$646,0)),"") -> FRAMBUESA LIOFILIZADA | E51: =IFERROR(INDEX('CONSOLIDADO PRECIOS'!$A$5:$A$646,MATCH(LARGE('CONSOLIDADO PRECIOS'!$U$5:$U$646,2),'CONSOLIDADO PRECIOS'!$U$5:$U$646,0)),"") -> ABARROTE | H51: =IFERROR(LARGE('CONSOLIDADO PRECIOS'!$U$5:$U$646,2),"") -> 173730.7
B52: =IFERROR(INDEX('CONSOLIDADO PRECIOS'!$B$5:$B$646,MATCH(LARGE('CONSOLIDADO PRECIOS'!$U$5:$U$646,3),'CONSOLIDADO PRECIOS'!$U$5:$U$646,0)),"") -> MARACUYA CRISPY | E52: =IFERROR(INDEX('CONSOLIDADO PRECIOS'!$A$5:$A$646,MATCH(LARGE('CONSOLIDADO PRECIOS'!$U$5:$U$646,3),'CONSOLIDADO PRECIOS'!$U$5:$U$646,0)),"") -> ABARROTE | H52: =IFERROR(LARGE('CONSOLIDADO PRECIOS'!$U$5:$U$646,3),"") -> 170623.2
B53: =IFERROR(INDEX('CONSOLIDADO PRECIOS'!$B$5:$B$646,MATCH(LARGE('CONSOLIDADO PRECIOS'!$U$5:$U$646,4),'CONSOLIDADO PRECIOS'!$U$5:$U$646,0)),"") -> POTATOWHIP | E53: =IFERROR(INDEX('CONSOLIDADO PRECIOS'!$A$5:$A$646,MATCH(LARGE('CONSOLIDADO PRECIOS'!$U$5:$U$646,4),'CONSOLIDADO PRECIOS'!$U$5:$U$646,0)),"") -> ABARROTE | H53: =IFERROR(LARGE('CONSOLIDADO PRECIOS'!$U$5:$U$646,4),"") -> 157881.17
B54: =IFERROR(INDEX('CONSOLIDADO PRECIOS'!$B$5:$B$646,MATCH(LARGE('CONSOLIDADO PRECIOS'!$U$5:$U$646,5),'CONSOLIDADO PRECIOS'!$U$5:$U$646,0)),"") -> ESENCIA DE FRAMBUESA | E54: =IFERROR(INDEX('CONSOLIDADO PRECIOS'!$A$5:$A$646,MATCH(LARGE('CONSOLIDADO PRECIOS'!$U$5:$U$646,5),'CONSOLIDADO PRECIOS'!$U$5:$U$646,0)),"") -> ABARROTE | H54: =IFERROR(LARGE('CONSOLIDADO PRECIOS'!$U$5:$U$646,5),"") -> 130162.27
B55: =IFERROR(INDEX('CONSOLIDADO PRECIOS'!$B$5:$B$646,MATCH(LARGE('CONSOLIDADO PRECIOS'!$U$5:$U$646,6),'CONSOLIDADO PRECIOS'!$U$5:$U$646,0)),"") -> ESENCIA DE PIÑA | E55: =IFERROR(INDEX('CONSOLIDADO PRECIOS'!$A$5:$A$646,MATCH(LARGE('CONSOLIDADO PRECIOS'!$U$5:$U$646,6),'CONSOLIDADO PRECIOS'!$U$5:$U$646,0)),"") -> ABARROTE | H55: =IFERROR(LARGE('CONSOLIDADO PRECIOS'!$U$5:$U$646,6),"") -> 128711
B56: =IFERROR(INDEX('CONSOLIDADO PRECIOS'!$B$5:$B$646,MATCH(LARGE('CONSOLIDADO PRECIOS'!$U$5:$U$646,7),'CONSOLIDADO PRECIOS'!$U$5:$U$646,0)),"") -> ALGINATO DE SODIO | E56: =IFERROR(INDEX('CONSOLIDADO PRECIOS'!$A$5:$A$646,MATCH(LARGE('CONSOLIDADO PRECIOS'!$U$5:$U$646,7),'CONSOLIDADO PRECIOS'!$U$5:$U$646,0)),"") -> ABARROTE | H56: =IFERROR(LARGE('CONSOLIDADO PRECIOS'!$U$5:$U$646,7),"") -> 114726.7
B57: =IFERROR(INDEX('CONSOLIDADO PRECIOS'!$B$5:$B$646,MATCH(LARGE('CONSOLIDADO PRECIOS'!$U$5:$U$646,8),'CONSOLIDADO PRECIOS'!$U$5:$U$646,0)),"") -> GOMA KAPPA | E57: =IFERROR(INDEX('CONSOLIDADO PRECIOS'!$A$5:$A$646,MATCH(LARGE('CONSOLIDADO PRECIOS'!$U$5:$U$646,8),'CONSOLIDADO PRECIOS'!$U$5:$U$646,0)),"") -> ABARROTE | H57: =IFERROR(LARGE('CONSOLIDADO PRECIOS'!$U$5:$U$646,8),"") -> 95434.533
B58: =IFERROR(INDEX('CONSOLIDADO PRECIOS'!$B$5:$B$646,MATCH(LARGE('CONSOLIDADO PRECIOS'!$U$5:$U$646,9),'CONSOLIDADO PRECIOS'!$U$5:$U$646,0)),"") -> PEPERONCCINO O CHILE EN HOJUELAS | E58: =IFERROR(INDEX('CONSOLIDADO PRECIOS'!$A$5:$A$646,MATCH(LARGE('CONSOLIDADO PRECIOS'!$U$5:$U$646,9),'CONSOLIDADO PRECIOS'!$U$5:$U$646,0)),"") -> ABARROTE | H58: =IFERROR(LARGE('CONSOLIDADO PRECIOS'!$U$5:$U$646,9),"") -> 94822.933
B59: =IFERROR(INDEX('CONSOLIDADO PRECIOS'!$B$5:$B$646,MATCH(LARGE('CONSOLIDADO PRECIOS'!$U$5:$U$646,10),'CONSOLIDADO PRECIOS'!$U$5:$U$646,0)),"") -> TE MATCHA | E59: =IFERROR(INDEX('CONSOLIDADO PRECIOS'!$A$5:$A$646,MATCH(LARGE('CONSOLIDADO PRECIOS'!$U$5:$U$646,10),'CONSOLIDADO PRECIOS'!$U$5:$U$646,0)),"") -> TE | H59: =IFERROR(LARGE('CONSOLIDADO PRECIOS'!$U$5:$U$646,10),"") -> 92763.733

Sheet PROVEEDORES
A1: MAESTRO DE PROVEEDORES
A2: EMPRESA | B2: TIPO | C2: ENCARGADO | D2: CORREO | E2: TELEFONO | F2: COND. PAGO | G2: DETALLE
A3: ACUICOLA ALAS SPA | B3: PESCADOS Y CAVIAR | C3: Felipe Tisné - Viviana Olmos | D3: ventas@kenoz.cl,ftisne@kenoz.cl,contabilidad@acuicolaalas.cl | E3: 56961682811 - 56224766094 | F3: 30 dias
A4: Agricola y Ganadera Santa Laura Spa | B4: CARNES | C4: MARIE HERRERA | D4: mherrera@ganaderasantalaura.cl | F4: 30 dias
A5: ANDES BLEND SPA | B5: VINOS | C5: Johana Guerra | D5: cobranzas@andesblend.cl,johana.guerra@andesblend.cl,rene.ayala@andesblend.cl,pablo.alvarez@andesblend.cl | E5: 569 27314288 - 56983623633 | F5: 30 dias
A6: Bidfood Chile SA | B6: ABARROTES | C6: ARELI | D6: pagos@bidfood.cl,pmolina@bidfood.cl | E6: 56225994444 - 56998038459 | F6: 30 dias | G6: verificar pagina web
A7: CASERITA EN CASA SPA | B7: FRUTAS Y VERDURAS | C7: Francisco Montaner | D7: caseritaencasa@gmail.com | E7: 56952069703 | F7: 30 dias
A8: COM Y DIST DE PRODUCTOS DEL MAR CHRISTIAN OLGUIN | B8: PESCADOS Y MARISCOS | C8: MARCELA UGARTE | D8: mudellarossa@gmail.com | E8: 56965657557 | F8: 30 dias
A9: Comercial Bastien | B9: REPOSTERIA Y PASTELERIA | C9: Paulina Medina | D9: pmedina@bastien.cl,ventas@bastien.cl | E9: 56223307540 | F9: 30 dias
A10: COMERCIAL BIOLACTEOS SPA | B10: CULTIVOS LIOFILIZADO EN POLVO | C10: Gonzalo Ortega | D10: gonzalo@fermentosdelsur.cl | E10: 56979639333 | F10: 30 dias
A11: COMERCIAL BOTE DE PESCA SPA | B11: MARISCOS Y PECADOS | C11: MAX HERRERA | D11: ventas@botedepesca.cl,max@botedepesca.cl,contabilidad@botedepesca.cl,nicolasklima@botedepesca.cl | E11: 56993435700 | F11: 30 dias
A12: Comercial Chau | B12: CARNES | C12: Ximena Marquez | D12: jefecobranza@comercialchau.com, ventas@buenacarne.cl,tesoreria@comercialchau.com,asistentecomercial2@comercialchau.com | E12: 56225853801 | F12: 30 dias
A13: COMERCIAL EDWARDS FINE WINES LTDA | B13: VINOS Y LICORES | C13: Diego Edwards | D13: dedwardj@uc.cl,ventas@efwines.cl | F13: 30 dias
A14: COMERCIAL SANTA CATALINA LTDA | B14: ABARROTES Y VERDURAS | C14: Juan Yañez Vargas | D14: santacatalina3@gmail.com | E14: 56996996469 | F14: 30 dias
A15: Comercial Sur Spa | B15: CONDIMENTOS Y ESPECIES | C15: Sebastian Dib - Maria Dib | D15: sdib@etnia.cl, medib@etnia.cl | E15: 56966473468 | F15: 30 dias
A16: COMERCIAL VALENZUELA COMPANIA LIMITADA | B16: MARISCOS | C16: MILLARAY VALENZUEA | D16: valenzuela.contabilidad@hotmail.com | F16: 30 dias
A17: Comercializador y Dist San Andres y CIA Ltda | B17: ABARROTES | C17: NICOLE LANAS | D17: COBRANZA@CSANANDRES.CL,nicole.lanas@csanandres.cl | E17: (32) 281 4893 | F17: 30 dias
A18: COMERCIALIZADORA AYM LTDA | D18: cecialvear@gmail.com | F18: 30 dias
A19: Comercializadora Benbo Spa | B19: HUEVOS | C19: Nicolas Borobio | D19: equipo@benbo.cl,ventas@benbo.cl | F19: 30 dias
A20: Comercializadora de copihues org Ltda | B20: COPIHUES | C20: JUAN PABLO | D20: plaza.juanpablo@gmail.com | F20: 30 dias
A21: FRUTERIA CENTRAL SPA | B21: FRUTAS Y VERDURAS | C21: GERALDINE ESCOBAR | D21: gescobargalvez@gmail.com | F21: 30 dias
A22: GOURMET SELECT LTDA | B22: ESPECIES | C22: Génesis Sanchez | D22: chef@gourmetselect.cl,contabilidad@gourmetselect.cl,pedidos@gourmetselect.cl,info@gourmetselect.cl | E22: 56944921093 | F22: 30 dias | G22: consultar web
A23: Grupo Dk Servicios Limitada | B23: ASEO | C23: Adriana Salazar - Yilsa Paredes | D23: contacto@grupodk.cl,asistente@grupodk.cl | E23: 56222767775 - 56954202544 - 950058344 | F23: 30 dias
A24: IMPORTADORA Y ALIMENTOS ICB FOOD SERVICE SPA | B24: ABARROTES | C24: ROXANA LUGO | D24: rlugo@icbfs.cl | E24: 56942914322 | F24: 30 dias
A25: La Vinoteca | B25: VINOS Y LICORES | C25: Johana Quiroga - Andrea Aristizabal | D25: andrea.aristizabal@lavinoteca.cl, johanna.quiroga@lavinoteca.cl, margarita.arias@lavinoteca.cl | E25: 56228292221 - 56992197824 | F25: 30 dias
A26: MARALMA FOOD SPA | B26: MARISCOS Y PESCADOS | C26: Felipe Mena - Areangel Gomez | D26: cobranzas@maralmafood.cl,felipemena@maralmafood.cl | E26: 56985044772 | F26: 30 dias
A27: MAURICIO CESAR DIAZ FERNANDEZ | B27: VINOS Y LICORES | C27: MAURICIO DIAZ | D27: licoval@licoval.cl | E27: 56992568880 | F27: 30 dias
A28: MAXIO2 LTDA (oxigeno y nitrogeno) | B28: NITROGENO | C28: JAIME LOPEZ | D28: maxi-o2@outlook.com | E28: 56942263934 | F28: contado
A29: MINIMARKET Y PROCESADORA MAURICIO ALFREDO REYES AROS EIRL | B29: ABARROTES | C29: Karla Vidal Aros | D29: karlaandrea.vidalaros500@gmail.com,mrsabores@gmail.com | E29: 56940685328 | F29: 30 dias
A30: MIRAI RAMEN SPA | B30: ESPORAS | C30: Ismael Poblete | D30: ismael@miraifoodlab.cl,pagos@miraifoodlab.cl | F30: 30 dias
A31: NATURALEZA FEMENINA SPA | B31: ABARROTES | C31: Karla Vidal Aros | D31: karlaandrea.vidalaros500@gmail.com,naturalezafemeninaspa@gmail.com | E31: 56940685328 | F31: 30 dias
A32: PALAIS GOURMET LIMITADA | B32: CARNES Y LACTEOS | C32: Camila Morales - Gonzalo Rivas | D32: grivas@palaisgourmet.cl | E32: 56942132129 | F32: 30 dias
A33: ROSA BUSTOS PARRA SPA | B33: MARISCOS Y PESCADOS | C33: ROSA BUSTOS | D33: rosa.bustos@distemar.cl,distemar.ryn@gmail.com | F33: 30 dias
A34: SOCIEDAD AGRICOLA LOS FAISANES LIMITADA | B34: CARNES EXOTICOS | D34: marcelloavatte@hotmail.com | F34: 30 dias
A35: SOCIEDAD GANADERA RODRIGUEZ Y GRASSI CIA LTDA | B35: CARNES | C35: Patricia Tapia | D35: gr.ganaderareal@gmail.com | E35: 56983670527 | F35: 30 dias
A36: TRUFEROSGRAU SPA | B36: TRUFAS Y HONGOS | C36: MIRENTXU | D36: facturacion@truferosgrau.cl,mruiz@truferosgrau.cl | E36: 56968024411 | F36: 30 dias
A37: NEUCOBER S.A | B37: CHOCOLATE | C37: DANIEL GONZALEZ | D37: danielgonzalez@neucober.cl | E37: 56978895811 | F37: 30 días
A38: Leche Fresca SpA | B38: Leche fresca pasteurizada | C38: LUIS INFANTE | D38: luis@frescarebeca.cl | E38: 56985008017 | F38: 30 días
A39: Agrogourmet | B39: Chocolateria | C39: Carolina Montezuma. | D39: carolina@agourmet.cl | E39: 56990220710 | F39: 30 días
A40: GRV | B40: ASEO | C40: MARITZA DE LA CERDA | D40: MARITZA.DELACERDA@GRV.CL; oscar.soto@grv.cl | E40: 56961247783 | F40: 30 días
...

Sheet CONSOLIDADO PRECIOS
A1: MAESTRO DE PRECIOS POR PROVEEDOR
A2: Factor de incremento: | B2: 0.1
A4: CATEGORÍA | B4: INGREDIENTE | C4: UM | D4: CANT. | E4: PROVEEDOR 1 | F4: TIPO | G4: CORREO | H4: TELÉFONO | I4: PRECIO P1 | J4: PROVEEDOR 2 | K4: TIPO | L4: CORREO | M4: TELÉFONO | N4: PRECIO P2 | O4: PROVEEDOR 3 | P4: TIPO | Q4: CORREO | R4: TELÉFONO | S4: PRECIO P3 | T4: PROMEDIO | U4: PRECIO ESTIMADO
A5: ABARROTE
A6: ABARROTE | B6: ACEITE DE CANOLA | C6: L | D6: 0.02 | E6: Bidfood Chile SA | F6: =IFERROR(VLOOKUP(E6,PROVEEDORES!$A$3:$G$42,2,0),"") -> ABARROTES | G6: =IFERROR(VLOOKUP(E6,PROVEEDORES!$A$3:$G$42,4,0),"") -> pagos@bidfood.cl,pmolina@bidfood.cl | H6: =IFERROR(VLOOKUP(E6,PROVEEDORES!$A$3:$G$42,5,0),"") -> 56225994444 - 56998038459 | I6: 3250 | J6: GOURMET SELECT LTDA | K6: =IFERROR(VLOOKUP(J6,PROVEEDORES!$A$3:$G$42,2,0),"") -> ESPECIES | L6: =IFERROR(VLOOKUP(J6,PROVEEDORES!$A$3:$G$42,4,0),"") -> chef@gourmetselect.cl,contabilidad@gourmetselect.cl,pedidos@gourmetselect.cl,info@gourmetselect.cl | M6: =IFERROR(VLOOKUP(J6,PROVEEDORES!$A$3:$G$42,5,0),"") -> 56944921093 | N6: 3484 | O6: CASERITA EN CASA SPA | P6: =IFERROR(VLOOKUP(O6,PROVEEDORES!$A$3:$G$42,2,0),"") -> FRUTAS Y VERDURAS | Q6: =IFERROR(VLOOKUP(O6,PROVEEDORES!$A$3:$G$42,4,0),"") -> caseritaencasa@gmail.com | R6: =IFERROR(VLOOKUP(O6,PROVEEDORES!$A$3:$G$42,5,0),"") -> 56952069703 | S6: 3043 | T6: =AVERAGE(I6,N6,S6) -> 3259 | U6: =T6*(1+$B$2) -> 3584.9
A7: ABARROTE | B7: ACEITE DE COCO | C7: L | D7: 0.01125 | E7: Bidfood Chile SA | F7: =IFERROR(VLOOKUP(E7,PROVEEDORES!$A$3:$G$42,2,0),"") -> ABARROTES | G7: =IFERROR(VLOOKUP(E7,PROVEEDORES!$A$3:$G$42,4,0),"") -> pagos@bidfood.cl,pmolina@bidfood.cl | H7: =IFERROR(VLOOKUP(E7,PROVEEDORES!$A$3:$G$42,5,0),"") -> 56225994444 - 56998038459 | I7: 10990 | J7: GOURMET SELECT LTDA | K7: =IFERROR(VLOOKUP(J7,PROVEEDORES!$A$3:$G$42,2,0),"") -> ESPECIES | L7: =IFERROR(VLOOKUP(J7,PROVEEDORES!$A$3:$G$42,4,0),"") -> chef@gourmetselect.cl,contabilidad@gourmetselect.cl,pedidos@gourmetselect.cl,info@gourmetselect.cl | M7: =IFERROR(VLOOKUP(J7,PROVEEDORES!$A$3:$G$42,5,0),"") -> 56944921093 | N7: 10281 | O7: CASERITA EN CASA SPA | P7: =IFERROR(VLOOKUP(O7,PROVEEDORES!$A$3:$G$42,2,0),"") -> FRUTAS Y VERDURAS | Q7: =IFERROR(VLOOKUP(O7,PROVEEDORES!$A$3:$G$42,4,0),"") -> caseritaencasa@gmail.com | R7: =IFERROR(VLOOKUP(O7,PROVEEDORES!$A$3:$G$42,5,0),"") -> 56952069703 | S7: 15100 | T7: =AVERAGE(I7,N7,S7) -> 12123.667 | U7: =T7*(1+$B$2) -> 13336.033
A8: ABARROTE | B8: ACEITE DE MAIZ | C8: L | D8: 0.00375 | E8: Bidfood Chile SA | F8: =IFERROR(VLOOKUP(E8,PROVEEDORES!$A$3:$G$42,2,0),"") -> ABARROTES | G8: =IFERROR(VLOOKUP(E8,PROVEEDORES!$A$3:$G$42,4,0),"") -> pagos@bidfood.cl,pmolina@bidfood.cl | H8: =IFERROR(VLOOKUP(E8,PROVEEDORES!$A$3:$G$42,5,0),"") -> 56225994444 - 56998038459 | I8: 4980 | J8: GOURMET SELECT LTDA | K8: =IFERROR(VLOOKUP(J8,PROVEEDORES!$A$3:$G$42,2,0),"") -> ESPECIES | L8: =IFERROR(VLOOKUP(J8,PROVEEDORES!$A$3:$G$42,4,0),"") -> chef@gourmetselect.cl,contabilidad@gourmetselect.cl,pedidos@gourmetselect.cl,info@gourmetselect.cl | M8: =IFERROR(VLOOKUP(J8,PROVEEDORES!$A$3:$G$42,5,0),"") -> 56944921093 | N8: 5316 | O8: CASERITA EN CASA SPA | P8: =IFERROR(VLOOKUP(O8,PROVEEDORES!$A$3:$G$42,2,0),"") -> FRUTAS Y VERDURAS | Q8: =IFERROR(VLOOKUP(O8,PROVEEDORES!$A$3:$G$42,4,0),"") -> caseritaencasa@gmail.com | R8: =IFERROR(VLOOKUP(O8,PROVEEDORES!$A$3:$G$42,5,0),"") -> 56952069703 | S8: 7763 | T8: =AVERAGE(I8,N8,S8) -> 6019.6667 | U8: =T8*(1+$B$2) -> 6621.6333
A9: ABARROTE | B9: ACEITE DE MARAVILLA | C9: L | D9: 1.756625 | E9: Bidfood Chile SA | F9: =IFERROR(VLOOKUP(E9,PROVEEDORES!$A$3:$G$42,2,0),"") -> ABARROTES | G9: =IFERROR(VLOOKUP(E9,PROVEEDORES!$A$3:$G$42,4,0),"") -> pagos@bidfood.cl,pmolina@bidfood.cl | H9: =IFERROR(VLOOKUP(E9,PROVEEDORES!$A$3:$G$42,5,0),"") -> 56225994444 - 56998038459 | I9: 2304 | J9: GOURMET SELECT LTDA | K9: =IFERROR(VLOOKUP(J9,PROVEEDORES!$A$3:$G$42,2,0),"") -> ESPECIES | L9: =IFERROR(VLOOKUP(J9,PROVEEDORES!$A$3:$G$42,4,0),"") -> chef@gourmetselect.cl,contabilidad@gourmetselect.cl,pedidos@gourmetselect.cl,info@gourmetselect.cl | M9: =IFERROR(VLOOKUP(J9,PROVEEDORES!$A$3:$G$42,5,0),"") -> 56944921093 | N9: 3448 | O9: CASERITA EN CASA SPA | P9: =IFERROR(VLOOKUP(O9,PROVEEDORES!$A$3:$G$42,2,0),"") -> FRUTAS Y VERDURAS | Q9: =IFERROR(VLOOKUP(O9,PROVEEDORES!$A$3:$G$42,4,0),"") -> caseritaencasa@gmail.com | R9: =IFERROR(VLOOKUP(O9,PROVEEDORES!$A$3:$G$42,5,0),"") -> 56952069703 | S9: 3850 | T9: =AVERAGE(I9,N9,S9) -> 3200.6667 | U9: =T9*(1+$B$2) -> 3520.7333
A10: ABARROTE | B10: ACEITE DE OLIVA | C10: L | D10: 1.0346875 | E10: Bidfood Chile SA | F10: =IFERROR(VLOOKUP(E10,PROVEEDORES!$A$3:$G$42,2,0),"") -> ABARROTES | G10: =IFERROR(VLOOKUP(E10,PROVEEDORES!$A$3:$G$42,4,0),"") -> pagos@bidfood.cl,pmolina@bidfood.cl | H10: =IFERROR(VLOOKUP(E10,PROVEEDORES!$A$3:$G$42,5,0),"") -> 56225994444 - 56998038459 | I10: 14516 | J10: GOURMET SELECT LTDA | K10: =IFERROR(VLOOKUP(J10,PROVEEDORES!$A$3:$G$42,2,0),"") -> ESPECIES | L10: =IFERROR(VLOOKUP(J10,PROVEEDORES!$A$3:$G$42,4,0),"") -> chef@gourmetselect.cl,contabilidad@gourmetselect.cl,pedidos@gourmetselect.cl,info@gourmetselect.cl | M10: =IFERROR(VLOOKUP(J10,PROVEEDORES!$A$3:$G$42,5,0),"") -> 56944921093 | N10: 18087 | O10: CASERITA EN CASA SPA | P10: =IFERROR(VLOOKUP(O10,PROVEEDORES!$A$3:$G$42,2,0),"") -> FRUTAS Y VERDURAS | Q10: =IFERROR(VLOOKUP(O10,PROVEEDORES!$A$3:$G$42,4,0),"") -> caseritaencasa@gmail.com | R10: =IFERROR(VLOOKUP(O10,PROVEEDORES!$A$3:$G$42,5,0),"") -> 56952069703 | S10: 15378 | T10: =AVERAGE(I10,N10,S10) -> 15993.667 | U10: =T10*(1+$B$2) -> 17593.033
A11: ABARROTE | B11: ACEITE DE SESAMO | C11: L | D11: 0.015625 | E11: Bidfood Chile SA | F11: =IFERROR(VLOOKUP(E11,PROVEEDORES!$A$3:$G$42,2,0),"") -> ABARROTES | G11: =IFERROR(VLOOKUP(E11,PROVEEDORES!$A$3:$G$42,4,0),"") -> pagos@bidfood.cl,pmolina@bidfood.cl | H11: =IFERROR(VLOOKUP(E11,PROVEEDORES!$A$3:$G$42,5,0),"") -> 56225994444 - 56998038459 | I11: 11872 | J11: GOURMET SELECT LTDA | K11: =IFERROR(VLOOKUP(J11,PROVEEDORES!$A$3:$G$42,2,0),"") -> ESPECIES | L11: =IFERROR(VLOOKUP(J11,PROVEEDORES!$A$3:$G$42,4,0),"") -> chef@gourmetselect.cl,contabilidad@gourmetselect.cl,pedidos@gourmetselect.cl,info@gourmetselect.cl | M11: =IFERROR(VLOOKUP(J11,PROVEEDORES!$A$3:$G$42,5,0),"") -> 56944921093 | N11: 16039 | O11: CASERITA EN CASA SPA | P11: =IFERROR(VLOOKUP(O11,PROVEEDORES!$A$3:$G$42,2,0),"") -> FRUTAS Y VERDURAS | Q11: =IFERROR(VLOOKUP(O11,PROVEEDORES!$A$3:$G$42,4,0),"") -> caseritaencasa@gmail.com | R11: =IFERROR(VLOOKUP(O11,PROVEEDORES!$A$3:$G$42,5,0),"") -> 56952069703 | S11: 1111 | T11: =AVERAGE(I11,N11,S11) -> 9674 | U11: =T11*(1+$B$2) -> 10641.4
A12: ABARROTE | B12: ACEITE PARA FREIR | C12: L | D12: 4.45 | E12: Bidfood Chile SA | F12: =IFERROR(VLOOKUP(E12,PROVEEDORES!$A$3:$G$42,2,0),"") -> ABARROTES | G12: =IFERROR(VLOOKUP(E12,PROVEEDORES!$A$3:$G$42,4,0),"") -> pagos@bidfood.cl,pmolina@bidfood.cl | H12: =IFERROR(VLOOKUP(E12,PROVEEDORES!$A$3:$G$42,5,0),"") -> 56225994444 - 56998038459 | I12: 2270 | J12: GOURMET SELECT LTDA | K12: =IFERROR(VLOOKUP(J12,PROVEEDORES!$A$3:$G$42,2,0),"") -> ESPECIES | L12: =IFERROR(VLOOKUP(J12,PROVEEDORES!$A$3:$G$42,4,0),"") -> chef@gourmetselect.cl,contabilidad@gourmetselect.cl,pedidos@gourmetselect.cl,info@gourmetselect.cl | M12: =IFERROR(VLOOKUP(J12,PROVEEDORES!$A$3:$G$42,5,0),"") -> 56944921093 | N12: 2832 | O12: CASERITA EN CASA SPA | P12: =IFERROR(VLOOKUP(O12,PROVEEDORES!$A$3:$G$42,2,0),"") -> FRUTAS Y VERDURAS | Q12: =IFERROR(VLOOKUP(O12,PROVEEDORES!$A$3:$G$42,4,0),"") -> caseritaencasa@gmail.com | R12: =IFERROR(VLOOKUP(O12,PROVEEDORES!$A$3:$G$42,5,0),"") -> 56952069703 | S12: 927 | T12: =AVERAGE(I12,N12,S12) -> 2009.6667 | U12: =T12*(1+$B$2) -> 2210.6333
A13: ABARROTE | B13: ACEITE SEMILLA DE GIRASOL | C13: L | D13: 0.1725 | E13: Bidfood Chile SA | F13: =IFERROR(VLOOKUP(E13,PROVEEDORES!$A$3:$G$42,2,0),"") -> ABARROTES | G13: =IFERROR(VLOOKUP(E13,PROVEEDORES!$A$3:$G$42,4,0),"") -> pagos@bidfood.cl,pmolina@bidfood.cl | H13: =IFERROR(VLOOKUP(E13,PROVEEDORES!$A$3:$G$42,5,0),"") -> 56225994444 - 56998038459 | I13: 3878 | J13: GOURMET SELECT LTDA | K13: =IFERROR(VLOOKUP(J13,PROVEEDORES!$A$3:$G$42,2,0),"") -> ESPECIES | L13: =IFERROR(VLOOKUP(J13,PROVEEDORES!$A$3:$G$42,4,0),"") -> chef@gourmetselect.cl,contabilidad@gourmetselect.cl,pedidos@gourmetselect.cl,info@gourmetselect.cl | M13: =IFERROR(VLOOKUP(J13,PROVEEDORES!$A$3:$G$42,5,0),"") -> 56944921093 | N13: 1045 | O13: CASERITA EN CASA SPA | P13: =IFERROR(VLOOKUP(O13,PROVEEDORES!$A$3:$G$42,2,0),"") -> FRUTAS Y VERDURAS | Q13: =IFERROR(VLOOKUP(O13,PROVEEDORES!$A$3:$G$42,4,0),"") -> caseritaencasa@gmail.com | R13: =IFERROR(VLOOKUP(O13,PROVEEDORES!$A$3:$G$42,5,0),"") -> 56952069703 | S13: 2914 | T13: =AVERAGE(I13,N13,S13) -> 2612.3333 | U13: =T13*(1+$B$2) -> 2873.5667
A14: ABARROTE | B14: ACEITE VEGETAL | C14: L | D14: 1.87825 | E14: Bidfood Chile SA | F14: =IFERROR(VLOOKUP(E14,PROVEEDORES!$A$3:$G$42,2,0),"") -> ABARROTES | G14: =IFERROR(VLOOKUP(E14,PROVEEDORES!$A$3:$G$42,4,0),"") -> pagos@bidfood.cl,pmolina@bidfood.cl | H14: =IFERROR(VLOOKUP(E14,PROVEEDORES!$A$3:$G$42,5,0),"") -> 56225994444 - 56998038459 | I14: 2300 | J14: GOURMET SELECT LTDA | K14: =IFERROR(VLOOKUP(J14,PROVEEDORES!$A$3:$G$42,2,0),"") -> ESPECIES | L14: =IFERROR(VLOOKUP(J14,PROVEEDORES!$A$3:$G$42,4,0),"") -> chef@gourmetselect.cl,contabilidad@gourmetselect.cl,pedidos@gourmetselect.cl,info@gourmetselect.cl | M14: =IFERROR(VLOOKUP(J14,PROVEEDORES!$A$3:$G$42,5,0),"") -> 56944921093 | N14: 3014 | O14: CASERITA EN CASA SPA | P14: =IFERROR(VLOOKUP(O14,PROVEEDORES!$A$3:$G$42,2,0),"") -> FRUTAS Y VERDURAS | Q14: =IFERROR(VLOOKUP(O14,PROVEEDORES!$A$3:$G$42,4,0),"") -> caseritaencasa@gmail.com | R14: =IFERROR(VLOOKUP(O14,PROVEEDORES!$A$3:$G$42,5,0),"") -> 56952069703 | S14: 838 | T14: =AVERAGE(I14,N14,S14) -> 2050.6667 | U14: =T14*(1+$B$2) -> 2255.7333
A15: ABARROTE | B15: ACEITUNAS MORADAS | C15: kg | D15: 0.015625 | E15: Bidfood Chile SA | F15: =IFERROR(VLOOKUP(E15,PROVEEDORES!$A$3:$G$42,2,0),"") -> ABARROTES | G15: =IFERROR(VLOOKUP(E15,PROVEEDORES!$A$3:$G$42,4,0),"") -> pagos@bidfood.cl,pmolina@bidfood.cl | H15: =IFERROR(VLOOKUP(E15,PROVEEDORES!$A$3:$G$42,5,0),"") -> 56225994444 - 56998038459 | I15: 8194 | J15: GOURMET SELECT LTDA | K15: =IFERROR(VLOOKUP(J15,PROVEEDORES!$A$3:$G$42,2,0),"") -> ESPECIES | L15: =IFERROR(VLOOKUP(J15,PROVEEDORES!$A$3:$G$42,4,0),"") -> chef@gourmetselect.cl,contabilidad@gourmetselect.cl,pedidos@gourmetselect.cl,info@gourmetselect.cl | M15: =IFERROR(VLOOKUP(J15,PROVEEDORES!$A$3:$G$42,5,0),"") -> 56944921093 | N15: 5048 | O15: CASERITA EN CASA SPA | P15: =IFERROR(VLOOKUP(O15,PROVEEDORES!$A$3:$G$42,2,0),"") -> FRUTAS Y VERDURAS | Q15: =IFERROR(VLOOKUP(O15,PROVEEDORES!$A$3:$G$42,4,0),"") -> caseritaencasa@gmail.com | R15: =IFERROR(VLOOKUP(O15,PROVEEDORES!$A$3:$G$42,5,0),"") -> 56952069703 | S15: 5292 | T15: =AVERAGE(I15,N15,S15) -> 6178 | U15: =T15*(1+$B$2) -> 6795.8
A16: ABARROTE | B16: ACEITUNAS NEGRAS C/HUESO | C16: kg | D16: 0.009375 | E16: Bidfood Chile SA | F16: =IFERROR(VLOOKUP(E16,PROVEEDORES!$A$3:$G$42,2,0),"") -> ABARROTES | G16: =IFERROR(VLOOKUP(E16,PROVEEDORES!$A$3:$G$42,4,0),"") -> pagos@bidfood.cl,pmolina@bidfood.cl | H16: =IFERROR(VLOOKUP(E16,PROVEEDORES!$A$3:$G$42,5,0),"") -> 56225994444 - 56998038459 | I16: 4522 | J16: GOURMET SELECT LTDA | K16: =IFERROR(VLOOKUP(J16,PROVEEDORES!$A$3:$G$42,2,0),"") -> ESPECIES | L16: =IFERROR(VLOOKUP(J16,PROVEEDORES!$A$3:$G$42,4,0),"") -> chef@gourmetselect.cl,contabilidad@gourmetselect.cl,pedidos@gourmetselect.cl,info@gourmetselect.cl | M16: =IFERROR(VLOOKUP(J16,PROVEEDORES!$A$3:$G$42,5,0),"") -> 56944921093 | N16: 2860 | O16: CASERITA EN CASA SPA | P16: =IFERROR(VLOOKUP(O16,PROVEEDORES!$A$3:$G$42,2,0),"") -> FRUTAS Y VERDURAS | Q16: =IFERROR(VLOOKUP(O16,PROVEEDORES!$A$3:$G$42,4,0),"") -> caseritaencasa@gmail.com | R16: =IFERROR(VLOOKUP(O16,PROVEEDORES!$A$3:$G$42,5,0),"") -> 56952069703 | S16: 2343 | T16: =AVERAGE(I16,N16,S16) -> 3241.6667 | U16: =T16*(1+$B$2) -> 3565.8333
A17: ABARROTE | B17: ACEITUNAS NEGRAS S/HUESO | C17: kg | D17: 0.2075 | E17: Bidfood Chile SA | F17: =IFERROR(VLOOKUP(E17,PROVEEDORES!$A$3:$G$42,2,0),"") -> ABARROTES | G17: =IFERROR(VLOOKUP(E17,PROVEEDORES!$A$3:$G$42,4,0),"") -> pagos@bidfood.cl,pmolina@bidfood.cl | H17: =IFERROR(VLOOKUP(E17,PROVEEDORES!$A$3:$G$42,5,0),"") -> 56225994444 - 56998038459 | I17: 5562 | J17: GOURMET SELECT LTDA | K17: =IFERROR(VLOOKUP(J17,PROVEEDORES!$A$3:$G$42,2,0),"") -> ESPECIES | L17: =IFERROR(VLOOKUP(J17,PROVEEDORES!$A$3:$G$42,4,0),"") -> chef@gourmetselect.cl,contabilidad@gourmetselect.cl,pedidos@gourmetselect.cl,info@gourmetselect.cl | M17: =IFERROR(VLOOKUP(J17,PROVEEDORES!$A$3:$G$42,5,0),"") -> 56944921093 | N17: 4511 | O17: CASERITA EN CASA SPA | P17: =IFERROR(VLOOKUP(O17,PROVEEDORES!$A$3:$G$42,2,0),"") -> FRUTAS Y VERDURAS | Q17: =IFERROR(VLOOKUP(O17,PROVEEDORES!$A$3:$G$42,4,0),"") -> caseritaencasa@gmail.com | R17: =IFERROR(VLOOKUP(O17,PROVEEDORES!$A$3:$G$42,5,0),"") -> 56952069703 | S17: 3372 | T17: =AVERAGE(I17,N17,S17) -> 4481.6667 | U17: =T17*(1+$B$2) -> 4929.8333
... A244: ABARROTE | B244: YUZU EN PASTA | C244: kg | D244: 0.003625 | E244: Bidfood Chile SA | F244: =IFERROR(VLOOKUP(E244,PROVEEDORES!$A$3:$G$42,2,0),"") -> ABARROTES | G244: =IFERROR(VLOOKUP(E244,PROVEEDORES!$A$3:$G$42,4,0),"") -> pagos@bidfood.cl,pmolina@bidfood.cl | H244: =IFERROR(VLOOKUP(E244,PROVEEDORES!$A$3:$G$42,5,0),"") -> 56225994444 - 56998038459 | I244: 27270 | J244: GOURMET SELECT LTDA | K244: =IFERROR(VLOOKUP(J244,PROVEEDORES!$A$3:$G$42,2,0),"") -> ESPECIES | L244: =IFERROR(VLOOKUP(J244,PROVEEDORES!$A$3:$G$42,4,0),"") -> chef@gourmetselect.cl,contabilidad@gourmetselect.cl,pedidos@gourmetselect.cl,info@gourmetselect.cl | M244: =IFERROR(VLOOKUP(J244,PROVEEDORES!$A$3:$G$42,5,0),"") -> 56944921093 | N244: 12544 | O244: CASERITA EN CASA SPA | P244: =IFERROR(VLOOKUP(O244,PROVEEDORES!$A$3:$G$42,2,0),"") -> FRUTAS Y VERDURAS | Q244: =IFERROR(VLOOKUP(O244,PROVEEDORES!$A$3:$G$42,4,0),"") -> caseritaencasa@gmail.com | R244: =IFERROR(VLOOKUP(O244,PROVEEDORES!$A$3:$G$42,5,0),"") -> 56952069703 | S244: 18571 | T244: =AVERAGE(I244,N244,S244) -> 19461.667 | U244: =T244*(1+$B$2) -> 21407.833
A245: AGUA
A246: AGUA | B246: AGUA DE ROSAS | C246: L | D246: 0.0025 | E246: Bidfood Chile SA | F246: =IFERROR(VLOOKUP(E246,PROVEEDORES!$A$3:$G$42,2,0),"") -> ABARROTES | G246: =IFERROR(VLOOKUP(E246,PROVEEDORES!$A$3:$G$42,4,0),"") -> pagos@bidfood.cl,pmolina@bidfood.cl | H246: =IFERROR(VLOOKUP(E246,PROVEEDORES!$A$3:$G$42,5,0),"") -> 56225994444 - 56998038459 | I246: 13919 | J246: GOURMET SELECT LTDA | K246: =IFERROR(VLOOKUP(J246,PROVEEDORES!$A$3:$G$42,2,0),"") -> ESPECIES | L246: =IFERROR(VLOOKUP(J246,PROVEEDORES!$A$3:$G$42,4,0),"") -> chef@gourmetselect.cl,contabilidad@gourmetselect.cl,pedidos@gourmetselect.cl,info@gourmetselect.cl | M246: =IFERROR(VLOOKUP(J246,PROVEEDORES!$A$3:$G$42,5,0),"") -> 56944921093 | N246: 12750 | T246: =AVERAGE(I246,N246) -> 13334.5 | U246: =T246*(1+$B$2) -> 14667.95
A247: AGUA | B247: AGUA MINERAL C/GAS | C247: L | D247: 0.05 | E247: Bidfood Chile SA | F247: =IFERROR(VLOOKUP(E247,PROVEEDORES!$A$3:$G$42,2,0),"") -> ABARROTES | G247: =IFERROR(VLOOKUP(E247,PROVEEDORES!$A$3:$G$42,4,0),"") -> pagos@bidfood.cl,pmolina@bidfood.cl | H247: =IFERROR(VLOOKUP(E247,PROVEEDORES!$A$3:$G$42,5,0),"") -> 56225994444 - 56998038459 | I247: 956 | J247: GOURMET SELECT LTDA | K247: =IFERROR(VLOOKUP(J247,PROVEEDORES!$A$3:$G$42,2,0),"") -> ESPECIES | L247: =IFERROR(VLOOKUP(J247,PROVEEDORES!$A$3:$G$42,4,0),"") -> chef@gourmetselect.cl,contabilidad@gourmetselect.cl,pedidos@gourmetselect.cl,info@gourmetselect.cl | M247: =IFERROR(VLOOKUP(J247,PROVEEDORES!$A$3:$G$42,5,0),"") -> 56944921093 | N247: 255 | T247: =AVERAGE(I247,N247) -> 605.5 | U247: =T247*(1+$B$2) -> 666.05
A248: ALGAS
A249: ALGAS | B249: LUCHE | C249: kg | D249: 0.00375 | E249: Bidfood Chile SA | F249: =IFERROR(VLOOKUP(E249,PROVEEDORES!$A$3:$G$42,2,0),"") -> ABARROTES | G249: =IFERROR(VLOOKUP(E249,PROVEEDORES!$A$3:$G$42,4,0),"") -> pagos@bidfood.cl,pmolina@bidfood.cl | H249: =IFERROR(VLOOKUP(E249,PROVEEDORES!$A$3:$G$42,5,0),"") -> 56225994444 - 56998038459 | I249: 14280 | J249: GOURMET SELECT LTDA | K249: =IFERROR(VLOOKUP(J249,PROVEEDORES!$A$3:$G$42,2,0),"") -> ESPECIES | L249: =IFERROR(VLOOKUP(J249,PROVEEDORES!$A$3:$G$42,4,0),"") -> chef@gourmetselect.cl,contabilidad@gourmetselect.cl,pedidos@gourmetselect.cl,info@gourmetselect.cl | M249: =IFERROR(VLOOKUP(J249,PROVEEDORES!$A$3:$G$42,5,0),"") -> 56944921093 | N249: 7126 | O249: CASERITA EN CASA SPA | P249: =IFERROR(VLOOKUP(O249,PROVEEDORES!$A$3:$G$42,2,0),"") -> FRUTAS Y VERDURAS | Q249: =IFERROR(VLOOKUP(O249,PROVEEDORES!$A$3:$G$42,4,0),"") -> caseritaencasa@gmail.com | R249: =IFERROR(VLOOKUP(O249,PROVEEDORES!$A$3:$G$42,5,0),"") -> 56952069703 | S249: 5389 | T249: =AVERAGE(I249,N249,S249) -> 8931.6667 | U249: =T249*(1+$B$2) -> 9824.8333
A250: ARTICULO COCINA
A251: ARTICULO COCINA | B251: ASTILLAS PARA AHUMAR | C251: kg | D251: 0.04375 | E251: Bidfood Chile SA | F251: =IFERROR(VLOOKUP(E251,PROVEEDORES!$A$3:$G$42,2,0),"") -> ABARROTES | G251: =IFERROR(VLOOKUP(E251,PROVEEDORES!$A$3:$G$42,4,0),"") -> pagos@bidfood.cl,pmolina@bidfood.cl | H251: =IFERROR(VLOOKUP(E251,PROVEEDORES!$A$3:$G$42,5,0),"") -> 56225994444 - 56998038459 | I251: 10000 | J251: GOURMET SELECT LTDA | K251: =IFERROR(VLOOKUP(J251,PROVEEDORES!$A$3:$G$42,2,0),"") -> ESPECIES | L251: =IFERROR(VLOOKUP(J251,PROVEEDORES!$A$3:$G$42,4,0),"") -> chef@gourmetselect.cl,contabilidad@gourmetselect.cl,pedidos@gourmetselect.cl,info@gourmetselect.cl | M251: =IFERROR(VLOOKUP(J251,PROVEEDORES!$A$3:$G$42,5,0),"") -> 56944921093 | N251: 8200 | O251: CASERITA EN CASA SPA | P251: =IFERROR(VLOOKUP(O251,PROVEEDORES!$A$3:$G$42,2,0),"") -> FRUTAS Y VERDURAS | Q251: =IFERROR(VLOOKUP(O251,PROVEEDORES!$A$3:$G$42,4,0),"") -> caseritaencasa@gmail.com | R251: =IFERROR(VLOOKUP(O251,PROVEEDORES!$A$3:$G$42,5,0),"") -> 56952069703 | S251: 13058 | T251: =AVERAGE(I251,N251,S251) -> 10419.333 | U251: =T251*(1+$B$2) -> 11461.267
A252: ARTICULO COCINA | B252: BASE CARTON TORTA 22 CM | C252: UN | D252: 3 | E252: Bidfood Chile SA | F252: =IFERROR(VLOOKUP(E252,PROVEEDORES!$A$3:$G$42,2,0),"") -> ABARROTES | G252: =IFERROR(VLOOKUP(E252,PROVEEDORES!$A$3:$G$42,4,0),"") -> pagos@bidfood.cl,pmolina@bidfood.cl | H252: =IFERROR(VLOOKUP(E252,PROVEEDORES!$A$3:$G$42,5,0),"") -> 56225994444 - 56998038459 | I252: 150 | J252: GOURMET SELECT LTDA | K252: =IFERROR(VLOOKUP(J252,PROVEEDORES!$A$3:$G$42,2,0),"") -> ESPECIES | L252: =IFERROR(VLOOKUP(J252,PROVEEDORES!$A$3:$G$42,4,0),"") -> chef@gourmetselect.cl,contabilidad@gourmetselect.cl,pedidos@gourmetselect.cl,info@gourmetselect.cl | M252: =IFERROR(VLOOKUP(J252,PROVEEDORES!$A$3:$G$42,5,0),"") -> 56944921093 | N252: 200 | O252: CASERITA EN CASA SPA | P252: =IFERROR(VLOOKUP(O252,PROVEEDORES!$A$3:$G$42,2,0),"") -> FRUTAS Y VERDURAS | Q252: =IFERROR(VLOOKUP(O252,PROVEEDORES!$A$3:$G$42,4,0),"") -> caseritaencasa@gmail.com | R252: =IFERROR(VLOOKUP(O252,PROVEEDORES!$A$3:$G$42,5,0),"") -> 56952069703 | S252: 185 | T252: =AVERAGE(I252,N252,S252) -> 178.33333 | U252: =T252*(1+$B$2) -> 196.16667
A253: ARTICULO COCINA | B253: BLONDA 22 CM | C253: UN | D253: 4 | E253: Bidfood Chile SA | F253: =IFERROR(VLOOKUP(E253,PROVEEDORES!$A$3:$G$42,2,0),"") -> ABARROTES | G253: =IFERROR(VLOOKUP(E253,PROVEEDORES!$A$3:$G$42,4,0),"") -> pagos@bidfood.cl,pmolina@bidfood.cl | H253: =IFERROR(VLOOKUP(E253,PROVEEDORES!$A$3:$G$42,5,0),"") -> 56225994444 - 56998038459 | I253: 300 | J253: GOURMET SELECT LTDA | K253: =IFERROR(VLOOKUP(J253,PROVEEDORES!$A$3:$G$42,2,0),"") -> ESPECIES | L253: =IFERROR(VLOOKUP(J253,PROVEEDORES!$A$3:$G$42,4,0),"") -> chef@gourmetselect.cl,contabilidad@gourmetselect.cl,pedidos@gourmetselect.cl,info@gourmetselect.cl | M253: =IFERROR(VLOOKUP(J253,PROVEEDORES!$A$3:$G$42,5,0),"") -> 56944921093 | N253: 415 | O253: CASERITA EN CASA SPA | P253: =IFERROR(VLOOKUP(O253,PROVEEDORES!$A$3:$G$42,2,0),"") -> FRUTAS Y VERDURAS | Q253: =IFERROR(VLOOKUP(O253,PROVEEDORES!$A$3:$G$42,4,0),"") -> caseritaencasa@gmail.com | R253: =IFERROR(VLOOKUP(O253,PROVEEDORES!$A$3:$G$42,5,0),"") -> 56952069703 | S253: 66 | T253: =AVERAGE(I253,N253,S253) -> 260.33333 | U253: =T253*(1+$B$2) -> 286.36667
A254: ARTICULO COCINA | B254: BOLSA PARA SELLADO AL VACIO 25X35 CM | C254: UN | D254: 2.75 | E254: Bidfood Chile SA | F254: =IFERROR(VLOOKUP(E254,PROVEEDORES!$A$3:$G$42,2,0),"") -> ABARROTES | G254: =IFERROR(VLOOKUP(E254,PROVEEDORES!$A$3:$G$42,4,0),"") -> pagos@bidfood.cl,pmolina@bidfood.cl | H254: =IFERROR(VLOOKUP(E254,PROVEEDORES!$A$3:$G$42,5,0),"") -> 56225994444 - 56998038459 | I254: 108 | J254: GOURMET SELECT LTDA | K254: =IFERROR(VLOOKUP(J254,PROVEEDORES!$A$3:$G$42,2,0),"") -> ESPECIES | L254: =IFERROR(VLOOKUP(J254,PROVEEDORES!$A$3:$G$42,4,0),"") -> chef@gourmetselect.cl,contabilidad@gourmetselect.cl,pedidos@gourmetselect.cl,info@gourmetselect.cl | M254: =IFERROR(VLOOKUP(J254,PROVEEDORES!$A$3:$G$42,5,0),"") -> 56944921093 | N254: 113 | O254: CASERITA EN CASA SPA | P254: =IFERROR(VLOOKUP(O254,PROVEEDORES!$A$3:$G$42,2,0),"") -> FRUTAS Y VERDURAS | Q254: =IFERROR(VLOOKUP(O254,PROVEEDORES!$A$3:$G$42,4,0),"") -> caseritaencasa@gmail.com | R254: =IFERROR(VLOOKUP(O254,PROVEEDORES!$A$3:$G$42,5,0),"") -> 56952069703 | S254: 199 | T254: =AVERAGE(I254,N254,S254) -> 140 | U254: =T254*(1+$B$2) -> 154
A255: ARTICULO COCINA | B255: BOLSA PARA SELLADO AL VACIO 30X40 CM | C255: UN | D255: 0.875 | E255: Bidfood Chile SA | F255: =IFERROR(VLOOKUP(E255,PROVEEDORES!$A$3:$G$42,2,0),"") -> ABARROTES | G255: =IFERROR(VLOOKUP(E255,PROVEEDORES!$A$3:$G$42,4,0),"") -> pagos@bidfood.cl,pmolina@bidfood.cl | H255: =IFERROR(VLOOKUP(E255,PROVEEDORES!$A$3:$G$42,5,0),"") -> 56225994444 - 56998038459 | I255: 150 | J255: GOURMET SELECT LTDA | K255: =IFERROR(VLOOKUP(J255,PROVEEDORES!$A$3:$G$42,2,0),"") -> ESPECIES | L255: =IFERROR(VLOOKUP(J255,PROVEEDORES!$A$3:$G$42,4,0),"") -> chef@gourmetselect.cl,contabilidad@gourmetselect.cl,pedidos@gourmetselect.cl,info@gourmetselect.cl | M255: =IFERROR(VLOOKUP(J255,PROVEEDORES!$A$3:$G$42,5,0),"") -> 56944921093 | N255: 74 | O255: CASERITA EN CASA SPA | P255: =IFERROR(VLOOKUP(O255,PROVEEDORES!$A$3:$G$42,2,0),"") -> FRUTAS Y VERDURAS | Q255: =IFERROR(VLOOKUP(O255,PROVEEDORES!$A$3:$G$42,4,0),"") -> caseritaencasa@gmail.com | R255: =IFERROR(VLOOKUP(O255,PROVEEDORES!$A$3:$G$42,5,0),"") -> 56952069703 | S255: 34 | T255: =AVERAGE(I255,N255,S255) -> 86 | U255: =T255*(1+$B$2) -> 94.6
A256: ARTICULO COCINA | B256: BOLSA PREPICADA 20 X 30 | C256: UN | D256: 4 | E256: Bidfood Chile SA | F256: =IFERROR(VLOOKUP(E256,PROVEEDORES!$A$3:$G$42,2,0),"") -> ABARROTES | G256: =IFERROR(VLOOKUP(E256,PROVEEDORES!$A$3:$G$42,4,0),"") -> pagos@bidfood.cl,pmolina@bidfood.cl | H256: =IFERROR(VLOOKUP(E256,PROVEEDORES!$A$3:$G$42,5,0),"") -> 56225994444 - 56998038459 | I256: 60 | J256: GOURMET SELECT LTDA | K256: =IFERROR(VLOOKUP(J256,PROVEEDORES!$A$3:$G$42,2,0),"") -> ESPECIES | L256: =IFERROR(VLOOKUP(J256,PROVEEDORES!$A$3:$G$42,4,0),"") -> chef@gourmetselect.cl,contabilidad@gourmetselect.cl,pedidos@gourmetselect.cl,info@gourmetselect.cl | M256: =IFERROR(VLOOKUP(J256,PROVEEDORES!$A$3:$G$42,5,0),"") -> 56944921093 | N256: 101 | O256: CASERITA EN CASA SPA | P256: =IFERROR(VLOOKUP(O256,PROVEEDORES!$A$3:$G$42,2,0),"") -> FRUTAS Y VERDURAS | Q256: =IFERROR(VLOOKUP(O256,PROVEEDORES!$A$3:$G$42,4,0),"") -> caseritaencasa@gmail.com | R256: =IFERROR(VLOOKUP(O256,PROVEEDORES!$A$3:$G$42,5,0),"") -> 56952069703 | S256: 17 | T256: =AVERAGE(I256,N256,S256) -> 59.333333 | U256: =T256*(1+$B$2) -> 65.266667
A257: ARTICULO COCINA | B257: BROCHETA DE BAMBU 10 CM 100 UNI | C257: UN | D257: 0.1 | E257: Bidfood Chile SA | F257: =IFERROR(VLOOKUP(E257,PROVEEDORES!$A$3:$G$42,2,0),"") -> ABARROTES | G257: =IFERROR(VLOOKUP(E257,PROVEEDORES!$A$3:$G$42,4,0),"") -> pagos@bidfood.cl,pmolina@bidfood.cl | H257: =IFERROR(VLOOKUP(E257,PROVEEDORES!$A$3:$G$42,5,0),"") -> 56225994444 - 56998038459 | I257: 590 | J257: GOURMET SELECT LTDA | K257: =IFERROR(VLOOKUP(J257,PROVEEDORES!$A$3:$G$42,2,0),"") -> ESPECIES | L257: =IFERROR(VLOOKUP(J257,PROVEEDORES!$A$3:$G$42,4,0),"") -> chef@gourmetselect.cl,contabilidad@gourmetselect.cl,pedidos@gourmetselect.cl,info@gourmetselect.cl | M257: =IFERROR(VLOOKUP(J257,PROVEEDORES!$A$3:$G$42,5,0),"") -> 56944921093 | N257: 199 | O257: CASERITA EN CASA SPA | P257: =IFERROR(VLOOKUP(O257,PROVEEDORES!$A$3:$G$42,2,0),"") -> FRUTAS Y VERDURAS | Q257: =IFERROR(VLOOKUP(O257,PROVEEDORES!$A$3:$G$42,4,0),"") -> caseritaencasa@gmail.com | R257: =IFERROR(VLOOKUP(O257,PROVEEDORES!$A$3:$G$42,5,0),"") -> 56952069703 | S257: 1004 | T257: =AVERAGE(I257,N257,S257) -> 597.66667 | U257: =T257*(1+$B$2) -> 657.43333
A258: ARTICULO COCINA | B258: BROCHETA DE BAMBU 12 CM 100 UN | C258: UN | D258: 0.226 | E258: Bidfood Chile SA | F258: =IFERROR(VLOOKUP(E258,PROVEEDORES!$A$3:$G$42,2,0),"") -> ABARROTES | G258: =IFERROR(VLOOKUP(E258,PROVEEDORES!$A$3:$G$42,4,0),"") -> pagos@bidfood.cl,pmolina@bidfood.cl | H258: =IFERROR(VLOOKUP(E258,PROVEEDORES!$A$3:$G$42,5,0),"") -> 56225994444 - 56998038459 | I258: 601 | J258: GOURMET SELECT LTDA | K258: =IFERROR(VLOOKUP(J258,PROVEEDORES!$A$3:$G$42,2,0),"") -> ESPECIES | L258: =IFERROR(VLOOKUP(J258,PROVEEDORES!$A$3:$G$42,4,0),"") -> chef@gourmetselect.cl,contabilidad@gourmetselect.cl,pedidos@gourmetselect.cl,info@gourmetselect.cl | M258: =IFERROR(VLOOKUP(J258,PROVEEDORES!$A$3:$G$42,5,0),"") -> 56944921093 | N258: 871 | O258: CASERITA EN CASA SPA | P258: =IFERROR(VLOOKUP(O258,PROVEEDORES!$A$3:$G$42,2,0),"") -> FRUTAS Y VERDURAS | Q258: =IFERROR(VLOOKUP(O258,PROVEEDORES!$A$3:$G$42,4,0),"") -> caseritaencasa@gmail.com | R258: =IFERROR(VLOOKUP(O258,PROVEEDORES!$A$3:$G$42,5,0),"") -> 56952069703 | S258: 339 | T258: =AVERAGE(I258,N258,S258) -> 603.66667 | U258: =T258*(1+$B$2) -> 664.03333
A259: ARTICULO COCINA | B259: BROCHETAS DE COCKTAIL 50 UN | C259: UN | D259: 0.1 | E259: Bidfood Chile SA | F259: =IFERROR(VLOOKUP(E259,PROVEEDORES!$A$3:$G$42,2,0),"") -> ABARROTES | G259: =IFERROR(VLOOKUP(E259,PROVEEDORES!$A$3:$G$42,4,0),"") -> pagos@bidfood.cl,pmolina@bidfood.cl | H259: =IFERROR(VLOOKUP(E259,PROVEEDORES!$A$3:$G$42,5,0),"") -> 56225994444 - 56998038459 | I259: 2513 | J259: GOURMET SELECT LTDA | K259: =IFERROR(VLOOKUP(J259,PROVEEDORES!$A$3:$G$42,2,0),"") -> ESPECIES | L259: =IFERROR(VLOOKUP(J259,PROVEEDORES!$A$3:$G$42,4,0),"") -> chef@gourmetselect.cl,contabilidad@gourmetselect.cl,pedidos@gourmetselect.cl,info@gourmetselect.cl | M259: =IFERROR(VLOOKUP(J259,PROVEEDORES!$A$3:$G$42,5,0),"") -> 56944921093 | N259: 873 | O259: CASERITA EN CASA SPA | P259: =IFERROR(VLOOKUP(O259,PROVEEDORES!$A$3:$G$42,2,0),"") -> FRUTAS Y VERDURAS | Q259: =IFERROR(VLOOKUP(O259,PROVEEDORES!$A$3:$G$42,4,0),"") -> caseritaencasa@gmail.com | R259: =IFERROR(VLOOKUP(O259,PROVEEDORES!$A$3:$G$42,5,0),"") -> 56952069703 | S259: 3469 | T259: =AVERAGE(I259,N259,S259) -> 2285 | U259: =T259*(1+$B$2) -> 2513.5
A260: ARTICULO COCINA | B260: CAJA PLUMAVIT DE 3L PARA HELADOS | C260: UN | D260: 0.5 | E260: Bidfood Chile SA | F260: =IFERROR(VLOOKUP(E260,PROVEEDORES!$A$3:$G$42,2,0),"") -> ABARROTES | G260: =IFERROR(VLOOKUP(E260,PROVEEDORES!$A$3:$G$42,4,0),"") -> pagos@bidfood.cl,pmolina@bidfood.cl | H260: =IFERROR(VLOOKUP(E260,PROVEEDORES!$A$3:$G$42,5,0),"") -> 56225994444 - 56998038459 | I260: 2390 | J260: GOURMET SELECT LTDA | K260: =IFERROR(VLOOKUP(J260,PROVEEDORES!$A$3:$G$42,2,0),"") -> ESPECIES | L260: =IFERROR(VLOOKUP(J260,PROVEEDORES!$A$3:$G$42,4,0),"") -> chef@gourmetselect.cl,contabilidad@gourmetselect.cl,pedidos@gourmetselect.cl,info@gourmetselect.cl | M260: =IFERROR(VLOOKUP(J260,PROVEEDORES!$A$3:$G$42,5,0),"") -> 56944921093 | N260: 2261 | O260: CASERITA EN CASA SPA | P260: =IFERROR(VLOOKUP(O260,PROVEEDORES!$A$3:$G$42,2,0),"") -> FRUTAS Y VERDURAS | Q260: =IFERROR(VLOOKUP(O260,PROVEEDORES!$A$3:$G$42,4,0),"") -> caseritaencasa@gmail.com | R260: =IFERROR(VLOOKUP(O260,PROVEEDORES!$A$3:$G$42,5,0),"") -> 56952069703 | S260: 1801 | T260: =AVERAGE(I260,N260,S260) -> 2150.6667 | U260: =T260*(1+$B$2) -> 2365.7333
A261: ARTICULO COCINA | B261: CAPSULAS CERECINADAS N°8 | C261: UN | D261: 2.5 | E261: Bidfood Chile SA | F261: =IFERROR(VLOOKUP(E261,PROVEEDORES!$A$3:$G$42,2,0),"") -> ABARROTES | G261: =IFERROR(VLOOKUP(E261,PROVEEDORES!$A$3:$G$42,4,0),"") -> pagos@bidfood.cl,pmolina@bidfood.cl | H261: =IFERROR(VLOOKUP(E261,PROVEEDORES!$A$3:$G$42,5,0),"") -> 56225994444 - 56998038459 | I261: 95 | J261: GOURMET SELECT LTDA | K261: =IFERROR(VLOOKUP(J261,PROVEEDORES!$A$3:$G$42,2,0),"") -> ESPECIES | L261: =IFERROR(VLOOKUP(J261,PROVEEDORES!$A$3:$G$42,4,0),"") -> chef@gourmetselect.cl,contabilidad@gourmetselect.cl,pedidos@gourmetselect.cl,info@gourmetselect.cl | M261: =IFERROR(VLOOKUP(J261,PROVEEDORES!$A$3:$G$42,5,0),"") -> 56944921093 | N261: 28 | O261: CASERITA EN CASA SPA | P261: =IFERROR(VLOOKUP(O261,PROVEEDORES!$A$3:$G$42,2,0),"") -> FRUTAS Y VERDURAS | Q261: =IFERROR(VLOOKUP(O261,PROVEEDORES!$A$3:$G$42,4,0),"") -> caseritaencasa@gmail.com | R261: =IFERROR(VLOOKUP(O261,PROVEEDORES!$A$3:$G$42,5,0),"") -> 56952069703 | S261: 128 | T261: =AVERAGE(I261,N261,S261) -> 83.666667 | U261: =T261*(1+$B$2) -> 92.033333
A262: ARTICULO COCINA | B262: CARGA DE SIFON | C262: UN | D262: 2 | E262: Bidfood Chile SA | F262: =IFERROR(VLOOKUP(E262,PROVEEDORES!$A$3:$G$42,2,0),"") -> ABARROTES | G262: =IFERROR(VLOOKUP(E262,PROVEEDORES!$A$3:$G$42,4,0),"") -> pagos@bidfood.cl,pmolina@bidfood.cl | H262: =IFERROR(VLOOKUP(E262,PROVEEDORES!$A$3:$G$42,5,0),"") -> 56225994444 - 56998038459 | I262: 1980 | J262: GOURMET SELECT LTDA | K262: =IFERROR(VLOOKUP(J262,PROVEEDORES!$A$3:$G$42,2,0),"") -> ESPECIES | L262: =IFERROR(VLOOKUP(J262,PROVEEDORES!$A$3:$G$42,4,0),"") -> chef@gourmetselect.cl,contabilidad@gourmetselect.cl,pedidos@gourmetselect.cl,info@gourmetselect.cl | M262: =IFERROR(VLOOKUP(J262,PROVEEDORES!$A$3:$G$42,5,0),"") -> 56944921093 | N262: 2482 | O262: CASERITA EN CASA SPA | P262: =IFERROR(VLOOKUP(O262,PROVEEDORES!$A$3:$G$42,2,0),"") -> FRUTAS Y VERDURAS | Q262: =IFERROR(VLOOKUP(O262,PROVEEDORES!$A$3:$G$42,4,0),"") -> caseritaencasa@gmail.com | R262: =IFERROR(VLOOKUP(O262,PROVEEDORES!$A$3:$G$42,5,0),"") -> 56952069703 | S262: 664 | T262: =AVERAGE(I262,N262,S262) -> 1708.6667 | U262: =T262*(1+$B$2) -> 1879.5333
... A284: ARTICULO COCINA | B284: VASOS TERMICOS | C284: UN | D284: 1.75 | E284: Bidfood Chile SA | F284: =IFERROR(VLOOKUP(E284,PROVEEDORES!$A$3:$G$42,2,0),"") -> ABARROTES | G284: =IFERROR(VLOOKUP(E284,PROVEEDORES!$A$3:$G$42,4,0),"") -> pagos@bidfood.cl,pmolina@bidfood.cl | H284: =IFERROR(VLOOKUP(E284,PROVEEDORES!$A$3:$G$42,5,0),"") -> 56225994444 - 56998038459 | I284: 25 | J284: GOURMET SELECT LTDA | K284: =IFERROR(VLOOKUP(J284,PROVEEDORES!$A$3:$G$42,2,0),"") -> ESPECIES | L284: =IFERROR(VLOOKUP(J284,PROVEEDORES!$A$3:$G$42,4,0),"") -> chef@gourmetselect.cl,contabilidad@gourmetselect.cl,pedidos@gourmetselect.cl,info@gourmetselect.cl | M284: =IFERROR(VLOOKUP(J284,PROVEEDORES!$A$3:$G$42,5,0),"") -> 56944921093 | N284: 27 | O284: CASERITA EN CASA SPA | P284: =IFERROR(VLOOKUP(O284,PROVEEDORES!$A$3:$G$42,2,0),"") -> FRUTAS Y VERDURAS | Q284: =IFERROR(VLOOKUP(O284,PROVEEDORES!$A$3:$G$42,4,0),"") -> caseritaencasa@gmail.com | R284: =IFERROR(VLOOKUP(O284,PROVEEDORES!$A$3:$G$42,5,0),"") -> 56952069703 | S284: 2 | T284: =AVERAGE(I284,N284,S284) -> 18 | U284: =T284*(1+$B$2) -> 19.8
A285: BROTES
A286: BROTES | B286: MIX MICROGREENS | C286: UN | D286: 0.1 | E286: Bidfood Chile SA | F286: =IFERROR(VLOOKUP(E286,PROVEEDORES!$A$3:$G$42,2,0),"") -> ABARROTES | G286: =IFERROR(VLOOKUP(E286,PROVEEDORES!$A$3:$G$42,4,0),"") -> pagos@bidfood.cl,pmolina@bidfood.cl | H286: =IFERROR(VLOOKUP(E286,PROVEEDORES!$A$3:$G$42,5,0),"") -> 56225994444 - 56998038459 | I286: 4100 | J286: GOURMET SELECT LTDA | K286: =IFERROR(VLOOKUP(J286,PROVEEDORES!$A$3:$G$42,2,0),"") -> ESPECIES | L286: =IFERROR(VLOOKUP(J286,PROVEEDORES!$A$3:$G$42,4,0),"") -> chef@gourmetselect.cl,contabilidad@gourmetselect.cl,pedidos@gourmetselect.cl,info@gourmetselect.cl | M286: =IFERROR(VLOOKUP(J286,PROVEEDORES!$A$3:$G$42,5,0),"") -> 56944921093 | N286: 3048 | O286: CASERITA EN CASA SPA | P286: =IFERROR(VLOOKUP(O286,PROVEEDORES!$A$3:$G$42,2,0),"") -> FRUTAS Y VERDURAS | Q286: =IFERROR(VLOOKUP(O286,PROVEEDORES!$A$3:$G$42,4,0),"") -> caseritaencasa@gmail.com | R286: =IFERROR(VLOOKUP(O286,PROVEEDORES!$A$3:$G$42,5,0),"") -> 56952069703 | S286: 2603 | T286: =AVERAGE(I286,N286,S286) -> 3250.3333 | U286: =T286*(1+$B$2) -> 3575.3667
A287: CABRITO
A288: CABRITO | B288: CABRITO | C288: kg | D288: 0.1 | E288: Bidfood Chile SA | F288: =IFERROR(VLOOKUP(E288,PROVEEDORES!$A$3:$G$42,2,0),"") -> ABARROTES | G288: =IFERROR(VLOOKUP(E288,PROVEEDORES!$A$3:$G$42,4,0),"") -> pagos@bidfood.cl,pmolina@bidfood.cl | H288: =IFERROR(VLOOKUP(E288,PROVEEDORES!$A$3:$G$42,5,0),"") -> 56225994444 - 56998038459 | I288: 33000 | J288: GOURMET SELECT LTDA | K288: =IFERROR(VLOOKUP(J288,PROVEEDORES!$A$3:$G$42,2,0),"") -> ESPECIES | L288: =IFERROR(VLOOKUP(J288,PROVEEDORES!$A$3:$G$42,4,0),"") -> chef@gourmetselect.cl,contabilidad@gourmetselect.cl,pedidos@gourmetselect.cl,info@gourmetselect.cl | M288: =IFERROR(VLOOKUP(J288,PROVEEDORES!$A$3:$G$42,5,0),"") -> 56944921093 | N288: 10676 | O288: CASERITA EN CASA SPA | P288: =IFERROR(VLOOKUP(O288,PROVEEDORES!$A$3:$G$42,2,0),"") -> FRUTAS Y VERDURAS | Q288: =IFERROR(VLOOKUP(O288,PROVEEDORES!$A$3:$G$42,4,0),"") -> caseritaencasa@gmail.com | R288: =IFERROR(VLOOKUP(O288,PROVEEDORES!$A$3:$G$42,5,0),"") -> 56952069703 | S288: 22691 | T288: =AVERAGE(I288,N288,S288) -> 22122.333 | U288: =T288*(1+$B$2) -> 24334.567
...

Sheet RESUMEN
A1: RESUMEN POR CATEGORIA
A2: CATEGORÍA | B2: N° PRODUCTOS | C2: COSTO PROM. ESTIMADO | D2: COSTO TOTAL ESTIMADO
A3: ABARROTE | B3: =COUNTIF('CONSOLIDADO PRECIOS'!$A$5:$A$646,A3) -> 240 | C3: =IFERROR(AVERAGEIF('CONSOLIDADO PRECIOS'!$A$5:$A$646,A3,'CONSOLIDADO PRECIOS'!$U$5:$U$646),0) -> 18165.546 | D3: =SUMIF('CONSOLIDADO PRECIOS'!$A$5:$A$646,A3,'CONSOLIDADO PRECIOS'!$U$5:$U$646) -> 4341565.4
A4: AGUA | B4: =COUNTIF('CONSOLIDADO PRECIOS'!$A$5:$A$646,A4) -> 3 | C4: =IFERROR(AVERAGEIF('CONSOLIDADO PRECIOS'!$A$5:$A$646,A4,'CONSOLIDADO PRECIOS'!$U$5:$U$646),0) -> 7667 | D4: =SUMIF('CONSOLIDADO PRECIOS'!$A$5:$A$646,A4,'CONSOLIDADO PRECIOS'!$U$5:$U$646) -> 15334
A5: ALGAS | B5: =COUNTIF('CONSOLIDADO PRECIOS'!$A$5:$A$646,A5) -> 2 | C5: =IFERROR(AVERAGEIF('CONSOLIDADO PRECIOS'!$A$5:$A$646,A5,'CONSOLIDADO PRECIOS'!$U$5:$U$646),0) -> 9824.8333 | D5: =SUMIF('CONSOLIDADO PRECIOS'!$A$5:$A$646,A5,'CONSOLIDADO PRECIOS'!$U$5:$U$646) -> 9824.8333
A6: ARTICULO COCINA | B6: =COUNTIF('CONSOLIDADO PRECIOS'!$A$5:$A$646,A6) -> 35 | C6: =IFERROR(AVERAGEIF('CONSOLIDADO PRECIOS'!$A$5:$A$646,A6,'CONSOLIDADO PRECIOS'!$U$5:$U$646),0) -> 2572.2529 | D6: =SUMIF('CONSOLIDADO PRECIOS'!$A$5:$A$646,A6,'CONSOLIDADO PRECIOS'!$U$5:$U$646) -> 87456.6
A7: BROTES | B7: =COUNTIF('CONSOLIDADO PRECIOS'!$A$5:$A$646,A7) -> 2 | C7: =IFERROR(AVERAGEIF('CONSOLIDADO PRECIOS'!$A$5:$A$646,A7,'CONSOLIDADO PRECIOS'!$U$5:$U$646),0) -> 3575.3667 | D7: =SUMIF('CONSOLIDADO PRECIOS'!$A$5:$A$646,A7,'CONSOLIDADO PRECIOS'!$U$5:$U$646) -> 3575.3667
A8: CABRITO | B8: =COUNTIF('CONSOLIDADO PRECIOS'!$A$5:$A$646,A8) -> 2 | C8: =IFERROR(AVERAGEIF('CONSOLIDADO PRECIOS'!$A$5:$A$646,A8,'CONSOLIDADO PRECIOS'!$U$5:$U$646),0) -> 24334.567 | D8: =SUMIF('CONSOLIDADO PRECIOS'!$A$5:$A$646,A8,'CONSOLIDADO PRECIOS'!$U$5:$U$646) -> 24334.567
A9: CERDO | B9: =COUNTIF('CONSOLIDADO PRECIOS'!$A$5:$A$646,A9) -> 22 | C9: =IFERROR(AVERAGEIF('CONSOLIDADO PRECIOS'!$A$5:$A$646,A9,'CONSOLIDADO PRECIOS'!$U$5:$U$646),0) -> 14539.905 | D9: =SUMIF('CONSOLIDADO PRECIOS'!$A$5:$A$646,A9,'CONSOLIDADO PRECIOS'!$U$5:$U$646) -> 305338
A10: CERVEZA | B10: =COUNTIF('CONSOLIDADO PRECIOS'!$A$5:$A$646,A10) -> 2 | C10: =IFERROR(AVERAGEIF('CONSOLIDADO PRECIOS'!$A$5:$A$646,A10,'CONSOLIDADO PRECIOS'!$U$5:$U$646),0) -> 5725.5 | D10: =SUMIF('CONSOLIDADO PRECIOS'!$A$5:$A$646,A10,'CONSOLIDADO PRECIOS'!$U$5:$U$646) -> 5725.5
A11: CHOCOLATE | B11: =COUNTIF('CONSOLIDADO PRECIOS'!$A$5:$A$646,A11) -> 22 | C11: =IFERROR(AVERAGEIF('CONSOLIDADO PRECIOS'!$A$5:$A$646,A11,'CONSOLIDADO PRECIOS'!$U$5:$U$646),0) -> 17098.417 | D11: =SUMIF('CONSOLIDADO PRECIOS'!$A$5:$A$646,A11,'CONSOLIDADO PRECIOS'!$U$5:$U$646) -> 359066.77
A12: COLORANTES | B12: =COUNTIF('CONSOLIDADO PRECIOS'!$A$5:$A$646,A12) -> 14 | C12: =IFERROR(AVERAGEIF('CONSOLIDADO PRECIOS'!$A$5:$A$646,A12,'CONSOLIDADO PRECIOS'!$U$5:$U$646),0) -> 19172.69 | D12: =SUMIF('CONSOLIDADO PRECIOS'!$A$5:$A$646,A12,'CONSOLIDADO PRECIOS'!$U$5:$U$646) -> 249244.97
A13: CONGELADO | B13: =COUNTIF('CONSOLIDADO PRECIOS'!$A$5:$A$646,A13) -> 14 | C13: =IFERROR(AVERAGEIF('CONSOLIDADO PRECIOS'!$A$5:$A$646,A13,'CONSOLIDADO PRECIOS'!$U$5:$U$646),0) -> 5833.1731 | D13: =SUMIF('CONSOLIDADO PRECIOS'!$A$5:$A$646,A13,'CONSOLIDADO PRECIOS'!$U$5:$U$646) -> 75831.25
A14: CONSERVA | B14: =COUNTIF('CONSOLIDADO PRECIOS'!$A$5:$A$646,A14) -> 5 | C14: =IFERROR(AVERAGEIF('CONSOLIDADO PRECIOS'!$A$5:$A$646,A14,'CONSOLIDADO PRECIOS'!$U$5:$U$646),0) -> 5490.5583 | D14: =SUMIF('CONSOLIDADO PRECIOS'!$A$5:$A$646,A14,'CONSOLIDADO PRECIOS'!$U$5:$U$646) -> 21962.233
... A36: YOGURT | B36: =COUNTIF('CONSOLIDADO PRECIOS'!$A$5:$A$646,A36) -> 4 | C36: =IFERROR(AVERAGEIF('CONSOLIDADO PRECIOS'!$A$5:$A$646,A36,'CONSOLIDADO PRECIOS'!$U$5:$U$646),0) -> 3064.8444 | D36: =SUMIF('CONSOLIDADO PRECIOS'!$A$5:$A$646,A36,'CONSOLIDADO PRECIOS'!$U$5:$U$646) -> 9194.5333
A37: TOTAL | B37: =SUM(B3:B36) -> 642 | D37: =SUM(D3:D36) -> 8279311.2
